Workbook

Sheet 得分变量数据
A1: 得分 城市 | B1: 城市分类 | C1: P | I1: I | N1: C | S1: O | AP1: 总分
C2: P1 | D2: P2 | E2: P3 | F2: P4 | G2: P（修正前） | H2: P（修正后） | I2: I1 | J2: I2 | K2: I3 | L2: I4 | M2: I | N2: C1 | O2: C2 | P2: C3 | Q2: C4 | R2: C | S2: O1-1 | T2: O1 | U2: O2-1 | V2: O2-2 | W2: O2-3 | X2: O2 | Y2: O3-1 | Z2: O3-2 | AA2: O3-3 | AB2: O3-4 | AC2: O3 | AD2: O4-1 | AE2: O4-2 | AF2: O4-3 | AG2: O4-4 | AH2: O4-5 | AI2: O4 | AJ2: O（修正前） | AK2: O（修正后） | AL2: A1 | AM2: A2 | AN2: A
A3: 重庆市 | B3: 1 | C3: 65 | D3: 80 | E3: 75 | F3: 100 | G3: =AVERAGE(C3:F3) -> 80 | H3: =G3*K值!M4 -> 82.798646 | I3: 50 | J3: 40 | K3: 75 | L3: 100 | M3: =AVERAGE(I3:L3) -> 66.25 | N3: 100 | O3: 65 | P3: 35 | Q3: 100 | R3: =AVERAGE(N3:Q3) -> 75 | S3: 29.893957 | T3: =AVERAGE(S3) -> 29.893957 | U3: 53.677206 | V3: 66.187362 | W3: 93.692572 | X3: =AVERAGE(U3:W3) -> 71.185713 | Y3: 100 | Z3: 79.57477 | AA3: 88.548738 | AB3: 62.631783 | AC3: =AVERAGE(Y3:AB3) -> 82.688823 | AD3: 69.306802 | AE3: 29.730186 | AF3: 28.691983 | AG3: 7.8595407 | AH3: 100 | AI3: =AVERAGE(AD3:AH3) -> 47.117702 | AJ3: =AVERAGE(T3,X3,AC3,AI3) -> 57.721549 | AK3: =AJ3*K值!M4 -> 59.740826 | AL3: 75 | AM3: 50 | AN3: =AVERAGE(AL3:AM3) -> 62.5 | AP3: =(H3*0.2)+(M3*0.2)+(R3*0.1)+(AK3*0.4)+(AN3*0.1) -> 67.45606
A4: 上海市 | B4: 1 | C4: 100 | D4: 80 | E4: 75 | F4: 100 | G4: =AVERAGE(C4:F4) -> 88.75 | H4: =G4*K值!M5 -> 85.494974 | I4: 50 | J4: 100 | K4: 100 | L4: 100 | M4: =AVERAGE(I4:L4) -> 87.5 | N4: 100 | O4: 65 | P4: 100 | Q4: 65 | R4: =AVERAGE(N4:Q4) -> 82.5 | S4: 0 | T4: 0 | U4: 0 | V4: 56.048488 | W4: 100 | X4: =AVERAGE(U4:W4) -> 52.016163 | Y4: 100 | Z4: 100 | AA4: 100 | AB4: 49.591985 | AC4: =AVERAGE(Y4:AB4) -> 87.397996 | AD4: 100 | AE4: 44.595279 | AF4: 64.556962 | AG4: 3.9297703 | AH4: 28.200754 | AI4: =AVERAGE(AD4:AH4) -> 48.256553 | AJ4: =AVERAGE(T4,X4,AC4,AI4) -> 46.917678 | AK4: =AJ4*K值!M5 -> 45.196909 | AL4: 50 | AM4: 50 | AN4: =AVERAGE(AL4:AM4) -> 50 | AP4: =(H4*0.2)+(M4*0.2)+(R4*0.1)+(AK4*0.4)+(AN4*0.1) -> 65.927758
A5: 北京市 | B5: 1 | C5: 100 | D5: 100 | E5: 75 | F5: 100 | G5: =AVERAGE(C5:F5) -> 93.75 | H5: =G5*K值!M6 -> 90.311592 | I5: 100 | J5: 80 | K5: 100 | L5: 100 | M5: =AVERAGE(I5:L5) -> 95 | N5: 100 | O5: 65 | P5: 100 | Q5: 100 | R5: =AVERAGE(N5:Q5) -> 91.25 | S5: 0 | T5: 0 | U5: 0 | V5: 70.874171 | W5: 100 | X5: =AVERAGE(U5:W5) -> 56.958057 | Y5: 100 | Z5: 100 | AA5: 100 | AB5: 25.230317 | AC5: =AVERAGE(Y5:AB5) -> 81.307579 | AD5: 100 | AE5: 59.460371 | AF5: 78.902954 | AG5: 78.595407 | AH5: 100 | AI5: =AVERAGE(AD5:AH5) -> 83.391746 | AJ5: =AVERAGE(T5,X5,AC5,AI5) -> 55.414346 | AK5: =AJ5*K值!M6 -> 53.38195 | AL5: 100 | AM5: 75 | AN5: =AVERAGE(AL5:AM5) -> 87.5 | AP5: =(H5*0.2)+(M5*0.2)+(R5*0.1)+(AK5*0.4)+(AN5*0.1) -> 76.290098
A6: 成都市 | B6: 1 | C6: 65 | D6: 80 | E6: 100 | F6: 100 | G6: =AVERAGE(C6:F6) -> 86.25 | H6: =G6*K值!M7 -> 85.313122 | I6: 100 | J6: 100 | K6: 25 | L6: 100 | M6: =AVERAGE(I6:L6) -> 81.25 | N6: 65 | O6: 65 | P6: 100 | Q6: 100 | R6: =AVERAGE(N6:Q6) -> 82.5 | S6: 12.585841 | T6: =AVERAGE(S6) -> 12.585841 | U6: 43.332601 | V6: 45.666821 | W6: 98.884875 | X6: =AVERAGE(U6:W6) -> 62.628099 | Y6: 100 | Z6: 100 | AA6: 100 | AB6: 36.957712 | AC6: =AVERAGE(Y6:AB6) -> 84.239428 | AD6: 100 | AE6: 29.730186 | AF6: 71.729958 | AG6: 23.578622 | AH6: 58.570796 | AI6: =AVERAGE(AD6:AH6) -> 56.721912 | AJ6: =AVERAGE(T6,X6,AC6,AI6) -> 54.04382 | AK6: =AJ6*K值!M7 -> 53.456777 | AL6: 100 | AM6: 75 | AN6: =AVERAGE(AL6:AM6) -> 87.5 | AP6: =(H6*0.2)+(M6*0.2)+(R6*0.1)+(AK6*0.4)+(AN6*0.1) -> 71.695335
A7: 广州市 | B7: 1 | C7: 65 | D7: 100 | E7: 100 | F7: 60 | G7: =AVERAGE(C7:F7) -> 81.25 | H7: =G7*K值!M8 -> 78.270046 | I7: 40 | J7: 80 | K7: 50 | L7: 100 | M7: =AVERAGE(I7:L7) -> 67.5 | N7: 100 | O7: 100 | P7: 65 | Q7: 65 | R7: =AVERAGE(N7:Q7) -> 82.5 | S7: 35.658579 | T7: =AVERAGE(S7) -> 35.658579 | U7: 24.789606 | V7: 11.497678 | W7: 90.13811 | X7: =AVERAGE(U7:W7) -> 42.141798 | Y7: 100 | Z7: 100 | AA7: 100 | AB7: 6.1190239 | AC7: =AVERAGE(Y7:AB7) -> 76.529756 | AD7: 100 | AE7: 44.595279 | AF7: 60.337553 | AG7: 31.438163 | AH7: 100 | AI7: =AVERAGE(AD7:AH7) -> 67.274199 | AJ7: =AVERAGE(T7,X7,AC7,AI7) -> 55.401083 | AK7: =AJ7*K值!M8 -> 53.369174 | AL7: 75 | AM7: 50 | AN7: =AVERAGE(AL7:AM7) -> 62.5 | AP7: =(H7*0.2)+(M7*0.2)+(R7*0.1)+(AK7*0.4)+(AN7*0.1) -> 65.001679
A8: 深圳市 | B8: 1 | C8: 65 | D8: 100 | E8: 100 | F8: 100 | G8: =AVERAGE(C8:F8) -> 91.25 | H8: =G8*K值!M9 -> 87.903283 | I8: 75 | J8: 60 | K8: 100 | L8: 100 | M8: =AVERAGE(I8:L8) -> 83.75 | N8: 100 | O8: 100 | P8: 65 | Q8: 100 | R8: =AVERAGE(N8:Q8) -> 91.25 | S8: 28.817784 | T8: =AVERAGE(S8) -> 28.817784 | U8: 7.1576082 | V8: 62.938865 | W8: 100 | X8: =AVERAGE(U8:W8) -> 56.698824 | Y8: 100 | Z8: 100 | AA8: 100 | AB8: 29.526031 | AC8: =AVERAGE(Y8:AB8) -> 82.381508 | AD8: 100 | AE8: 29.730186 | AF8: 13.50211 | AG8: 27.508392 | AH8: 19.523599 | AI8: =AVERAGE(AD8:AH8) -> 38.052857 | AJ8: =AVERAGE(T8,X8,AC8,AI8) -> 51.487743 | AK8: =AJ8*K值!M9 -> 49.599361 | AL8: 75 | AM8: 50 | AN8: =AVERAGE(AL8:AM8) -> 62.5 | AP8: =(H8*0.2)+(M8*0.2)+(R8*0.1)+(AK8*0.4)+(AN8*0.1) -> 69.545401
A9: 天津市 | B9: 1 | C9: 100 | D9: 100 | E9: 100 | F9: 100 | G9: =AVERAGE(C9:F9) -> 100 | H9: =G9*K值!M10 -> 97.517554 | I9: 40 | J9: 60 | K9: 75 | L9: 100 | M9: =AVERAGE(I9:L9) -> 68.75 | N9: 100 | O9: 100 | P9: 35 | Q9: 100 | R9: =AVERAGE(N9:Q9) -> 83.75 | S9: 18.411993 | T9: =AVERAGE(S9) -> 18.411993 | U9: 34.633484 | V9: 83.336473 | W9: 100 | X9: =AVERAGE(U9:W9) -> 72.656652 | Y9: 75.187882 | Z9: 33.654281 | AA9: 100 | AB9: 43.131436 | AC9: =AVERAGE(Y9:AB9) -> 62.9934 | AD9: 100 | AE9: 29.730186 | AF9: 0 | AG9: 7.8595407 | AH9: 100 | AI9: =AVERAGE(AD9:AH9) -> 47.517945 | AJ9: =AVERAGE(T9,X9,AC9,AI9) -> 50.394998 | AK9: =AJ9*K值!M10 -> 49.143969 | AL9: 50 | AM9: 50 | AN9: =AVERAGE(AL9:AM9) -> 50 | AP9: =(H9*0.2)+(M9*0.2)+(R9*0.1)+(AK9*0.4)+(AN9*0.1) -> 66.286098
A10: 苏州市 | B10: 2 | C10: 65 | D10: 100 | E10: 100 | F10: 100 | G10: =AVERAGE(C10:F10) -> 91.25 | H10: =G10*K值!M11 -> 91.039945 | I10: 0 | J10: 40 | K10: 25 | L10: 25 | M10: =AVERAGE(I10:L10) -> 22.5 | N10: 35 | O10: 35 | P10: 35 | Q10: 65 | R10: =AVERAGE(N10:Q10) -> 42.5 | S10: 47.774271 | T10: =AVERAGE(S10) -> 47.774271 | U10: 33.284645 | V10: 48.826192 | W10: 100 | X10: =AVERAGE(U10:W10) -> 60.703612 | Y10: 38.471041 | Z10: 29.261628 | AA10: 100 | AB10: 20.313181 | AC10: =AVERAGE(Y10:AB10) -> 47.011462 | AD10: 64.809596 | AE10: 0 | AF10: 59.07173 | AG10: 19.648852 | AH10: 28.200754 | AI10: =AVERAGE(AD10:AH10) -> 34.346186 | AJ10: =AVERAGE(T10,X10,AC10,AI10) -> 47.458883 | AK10: =AJ10*K值!M11 -> 47.349634 | AL10: 25 | AM10: 50 | AN10: =AVERAGE(AL10:AM10) -> 37.5 | AP10: =(H10*0.2)+(M10*0.2)+(R10*0.1)+(AK10*0.4)+(AN10*0.1) -> 49.647843
A11: 郑州市 | B11: 1 | C11: 65 | D11: 60 | E11: 100 | F11: 60 | G11: =AVERAGE(C11:F11) -> 71.25 | H11: =G11*K值!M12 -> 68.85107 | I11: 20 | J11: 40 | K11: 25 | L11: 100 | M11: =AVERAGE(I11:L11) -> 46.25 | N11: 35 | O11: 35 | P11: 65 | Q11: 100 | R11: =AVERAGE(N11:Q11) -> 58.75 | S11: 41.240027 | T11: =AVERAGE(S11) -> 41.240027 | U11: 28.035691 | V11: 77.368091 | W11: 83.064034 | X11: =AVERAGE(U11:W11) -> 62.822605 | Y11: 67.941846 | Z11: 31.630585 | AA11: 82.325584 | AB11: 28.076987 | AC11: =AVERAGE(Y11:AB11) -> 52.49375 | AD11: 80.856269 | AE11: 29.730186 | AF11: 62.447257 | AG11: 19.648852 | AH11: 99.787282 | AI11: =AVERAGE(AD11:AH11) -> 58.493969 | AJ11: =AVERAGE(T11,X11,AC11,AI11) -> 53.762588 | AK11: =AJ11*K值!M12 -> 51.952445 | AL11: 75 | AM11: 50 | AN11: =AVERAGE(AL11:AM11) -> 62.5 | AP11: =(H11*0.2)+(M11*0.2)+(R11*0.1)+(AK11*0.4)+(AN11*0.1) -> 55.926192
A12: 武汉市 | B12: 1 | C12: 100 | D12: 80 | E12: 75 | F12: 75 | G12: =AVERAGE(C12:F12) -> 82.5 | H12: =G12*K值!M13 -> 79.474201 | I12: 25 | J12: 100 | K12: 25 | L12: 100 | M12: =AVERAGE(I12:L12) -> 62.5 | N12: 35 | O12: 65 | P12: 100 | Q12: 100 | R12: =AVERAGE(N12:Q12) -> 75 | S12: 7.2682031 | T12: =AVERAGE(S12) -> 7.2682031 | U12: 0 | V12: 60.65539 | W12: 97.804597 | X12: =AVERAGE(U12:W12) -> 52.819996 | Y12: 71.749355 | Z12: 73.475394 | AA12: 67.70492 | AB12: 62.098079 | AC12: =AVERAGE(Y12:AB12) -> 68.756937 | AD12: 57.40041 | AE12: 0 | AF12: 15.611814 | AG12: 7.8595407 | AH12: 6.5078662 | AI12: =AVERAGE(AD12:AH12) -> 17.475926 | AJ12: =AVERAGE(T12,X12,AC12,AI12) -> 36.580266 | AK12: =AJ12*K值!M13 -> 35.238635 | AL12: 100 | AM12: 75 | AN12: =AVERAGE(AL12:AM12) -> 87.5 | AP12: =(H12*0.2)+(M12*0.2)+(R12*0.1)+(AK12*0.4)+(AN12*0.1) -> 58.740294
A13: 西安市 | B13: 1 | C13: 100 | D13: 60 | E13: 75 | F13: 75 | G13: =AVERAGE(C13:F13) -> 77.5 | H13: =G13*K值!M14 -> 74.657583 | I13: 20 | J13: 40 | K13: 25 | L13: 100 | M13: =AVERAGE(I13:L13) -> 46.25 | N13: 100 | O13: 100 | P13: 100 | Q13: 65 | R13: =AVERAGE(N13:Q13) -> 91.25 | S13: 16.341251 | T13: =AVERAGE(S13) -> 16.341251 | U13: 30.539888 | V13: 67.579575 | W13: 99.965152 | X13: =AVERAGE(U13:W13) -> 66.028205 | Y13: 98.882453 | Z13: 74.202909 | AA13: 74.527896 | AB13: 40.296323 | AC13: =AVERAGE(Y13:AB13) -> 71.977396 | AD13: 56.369324 | AE13: 14.865093 | AF13: 17.299578 | AG13: 7.8595407 | AH13: 47.724352 | AI13: =AVERAGE(AD13:AH13) -> 28.823578 | AJ13: =AVERAGE(T13,X13,AC13,AI13) -> 45.792607 | AK13: =AJ13*K值!M14 -> 44.113102 | AL13: 50 | AM13: 50 | AN13: =AVERAGE(AL13:AM13) -> 50 | AP13: =(H13*0.2)+(M13*0.2)+(R13*0.1)+(AK13*0.4)+(AN13*0.1) -> 55.951757
A14: 杭州市 | B14: 1 | C14: 65 | D14: 100 | E14: 100 | F14: 100 | G14: =AVERAGE(C14:F14) -> 91.25 | H14: =G14*K值!M15 -> 89.365719 | I14: 75 | J14: 80 | K14: 100 | L14: 100 | M14: =AVERAGE(I14:L14) -> 88.75 | N14: 100 | O14: 35 | P14: 100 | Q14: 100 | R14: =AVERAGE(N14:Q14) -> 83.75 | S14: 28.374403 | T14: =AVERAGE(S14) -> 28.374403 | U14: 17.084416 | V14: 57.434554 | W14: 100 | X14: =AVERAGE(U14:W14) -> 58.17299 | Y14: 80.227376 | Z14: 65.032448 | AA14: 94.397003 | AB14: 23.255857 | AC14: =AVERAGE(Y14:AB14) -> 65.728171 | AD14: 100 | AE14: 29.730186 | AF14: 73.417722 | AG14: 23.578622 | AH14: 91.110127 | AI14: =AVERAGE(AD14:AH14) -> 63.567331 | AJ14: =AVERAGE(T14,X14,AC14,AI14) -> 53.960724 | AK14: =AJ14*K值!M15 -> 52.846454 | AL14: 100 | AM14: 50 | AN14: =AVERAGE(AL14:AM14) -> 75 | AP14: =(H14*0.2)+(M14*0.2)+(R14*0.1)+(AK14*0.4)+(AN14*0.1) -> 72.636725
A15: 保定市 | B15: 2 | C15: 65 | D15: 80 | E15: 60 | F15: 60 | G15: =AVERAGE(C15:F15) -> 66.25 | H15: =G15*K值!M16 -> 69.495406 | I15: 25 | J15: 0 | K15: 25 | L15: 0 | M15: =AVERAGE(I15:L15) -> 12.5 | N15: 65 | O15: 0 | P15: 65 | Q15: 0 | R15: =AVERAGE(N15:Q15) -> 32.5 | S15: 70.776254 | T15: =AVERAGE(S15) -> 70.776254 | U15: 67.42362 | V15: 85.601508 | W15: 93.657725 | X15: =AVERAGE(U15:W15) -> 82.227618 | Y15: 5.7419098 | Z15: 0.72388836 | AA15: 21.593596 | AB15: 60.537657 | AC15: =AVERAGE(Y15:AB15) -> 22.149263 | AD15: 16.703643 | AE15: 29.730186 | AF15: 51.054852 | AG15: 23.578622 | AH15: 26.031465 | AI15: =AVERAGE(AD15:AH15) -> 29.419754 | AJ15: =AVERAGE(T15,X15,AC15,AI15) -> 51.143222 | AK15: =AJ15*K值!M16 -> 53.648589 | AL15: 50 | AM15: 0 | AN15: =AVERAGE(AL15:AM15) -> 25 | AP15: =(H15*0.2)+(M15*0.2)+(R15*0.1)+(AK15*0.4)+(AN15*0.1) -> 43.608517
A16: 石家庄市 | B16: 2 | C16: 100 | D16: 80 | E16: 100 | F16: 100 | G16: =AVERAGE(C16:F16) -> 95 | H16: =G16*K值!M17 -> 95.219699 | I16: 40 | J16: 40 | K16: 75 | L16: 100 | M16: =AVERAGE(I16:L16) -> 63.75 | N16: 65 | O16: 65 | P16: 100 | Q16: 35 | R16: =AVERAGE(N16:Q16) -> 66.25 | S16: 61.457721 | T16: =AVERAGE(S16) -> 61.457721 | U16: 67.604633 | V16: 80.853233 | W16: 100 | X16: =AVERAGE(U16:W16) -> 82.819288 | Y16: 21.697652 | Z16: 6.6731192 | AA16: 30.665905 | AB16: 41.211619 | AC16: =AVERAGE(Y16:AB16) -> 25.062074 | AD16: 32.366199 | AE16: 0 | AF16: 0.42194093 | AG16: 3.9297703 | AH16: 23.862176 | AI16: =AVERAGE(AD16:AH16) -> 12.116017 | AJ16: =AVERAGE(T16,X16,AC16,AI16) -> 45.363775 | AK16: =AJ16*K值!M17 -> 45.468684 | AL16: 50 | AM16: 50 | AN16: =AVERAGE(AL16:AM16) -> 50 | AP16: =(H16*0.2)+(M16*0.2)+(R16*0.1)+(AK16*0.4)+(AN16*0.1) -> 61.606413
A17: 临沂市 | B17: 2 | C17: 65 | D17: 100 | E17: 75 | F17: 100 | G17: =AVERAGE(C17:F17) -> 85 | H17: =G17*K值!M18 -> 89.671975 | I17: 0 | J17: 60 | K17: 25 | L17: 25 | M17: =AVERAGE(I17:L17) -> 27.5 | N17: 65 | O17: 100 | P17: 100 | Q17: 100 | R17: =AVERAGE(N17:Q17) -> 91.25 | S17: 77.196442 | T17: =AVERAGE(S17) -> 77.196442 | U17: 70.406937 | V17: 83.413306 | W17: 88.116946 | X17: =AVERAGE(U17:W17) -> 80.64573 | Y17: 5.7443615 | Z17: NA | AA17: 32.465371 | AB17: 18.575661 | AC17: =AVERAGE(Y17:AB17) -> 18.928465 | AD17: 24.328797 | AE17: 59.460371 | AF17: 100 | AG17: 0 | AH17: 49.893641 | AI17: =AVERAGE(AD17:AH17) -> 46.736562 | AJ17: =AVERAGE(T17,X17,AC17,AI17) -> 55.876799 | AK17: =AJ17*K值!M18 -> 58.948035 | AL17: 50 | AM17: 0 | AN17: =AVERAGE(AL17:AM17) -> 25 | AP17: =(H17*0.2)+(M17*0.2)+(R17*0.1)+(AK17*0.4)+(AN17*0.1) -> 58.638609
A18: 东莞市 | B18: 1 | C18: 65 | D18: 100 | E18: 100 | F18: 75 | G18: =AVERAGE(C18:F18) -> 85 | H18: =G18*K值!M19 -> 85.633561 | I18: 25 | J18: 60 | K18: 25 | L18: 25 | M18: =AVERAGE(I18:L18) -> 33.75 | N18: 35 | O18: 35 | P18: 100 | Q18: 35 | R18: =AVERAGE(N18:Q18) -> 51.25 | S18: 56.901491 | T18: =AVERAGE(S18) -> 56.901491 | U18: 41.230947 | V18: 59.167905 | W18: 95.400108 | X18: =AVERAGE(U18:W18) -> 65.26632 | Y18: NA | Z18: NA | AA18: 38.763503 | AB18: 100 | AC18: =AVERAGE(Y18:AB18) -> 69.381752 | AD18: 39.910092 | AE18: 14.865093 | AF18: 54.43038 | AG18: 58.946555 | AH18: 43.385775 | AI18: =AVERAGE(AD18:AH18) -> 42.307579 | AJ18: =AVERAGE(T18,X18,AC18,AI18) -> 58.464285 | AK18: =AJ18*K值!M19 -> 58.900058 | AL18: 50 | AM18: 50 | AN18: =AVERAGE(AL18:AM18) -> 50 | AP18: =(H18*0.2)+(M18*0.2)+(R18*0.1)+(AK18*0.4)+(AN18*0.1) -> 57.561735
A19: 青岛市 | B19: 1 | C19: 100 | D19: 60 | E19: 45 | F19: 100 | G19: =AVERAGE(C19:F19) -> 76.25 | H19: =G19*K值!M20 -> 75.667531 | I19: 50 | J19: 40 | K19: 75 | L19: 100 | M19: =AVERAGE(I19:L19) -> 66.25 | N19: 65 | O19: 65 | P19: 100 | Q19: 65 | R19: =AVERAGE(N19:Q19) -> 73.75 | S19: 47.875258 | T19: =AVERAGE(S19) -> 47.875258 | U19: 42.952236 | V19: 76.593615 | W19: 100 | X19: =AVERAGE(U19:W19) -> 73.18195 | Y19: 79.629158 | Z19: 17.976803 | AA19: 63.131276 | AB19: 38.30262 | AC19: =AVERAGE(Y19:AB19) -> 49.759964 | AD19: 47.395851 | AE19: 0 | AF19: 2.1097046 | AG19: 0 | AH19: 0 | AI19: =AVERAGE(AD19:AH19) -> 9.9011112 | AJ19: =AVERAGE(T19,X19,AC19,AI19) -> 45.179571 | AK19: =AJ19*K值!M20 -> 44.834447 | AL19: 100 | AM19: 25 | AN19: =AVERAGE(AL19:AM19) -> 62.5 | AP19: =(H19*0.2)+(M19*0.2)+(R19*0.1)+(AK19*0.4)+(AN19*0.1) -> 59.942285
A20: 长沙市 | B20: 1 | C20: 65 | D20: 80 | E20: 100 | F20: 75 | G20: =AVERAGE(C20:F20) -> 80 | H20: =G20*K值!M21 -> 77.568494 | I20: 50 | J20: 100 | K20: 50 | L20: 50 | M20: =AVERAGE(I20:L20) -> 62.5 | N20: 0 | O20: 65 | P20: 35 | Q20: 35 | R20: =AVERAGE(N20:Q20) -> 33.75 | S20: 28.900806 | T20: =AVERAGE(S20) -> 28.900806 | U20: 16.632256 | V20: 51.945609 | W20: 98.606093 | X20: =AVERAGE(U20:W20) -> 55.727986 | Y20: 50.631533 | Z20: 42.641232 | AA20: 57.208033 | AB20: 36.580028 | AC20: =AVERAGE(Y20:AB20) -> 46.765206 | AD20: 50.456602 | AE20: 29.730186 | AF20: 58.649789 | AG20: 0 | AH20: 56.401507 | AI20: =AVERAGE(AD20:AH20) -> 39.047617 | AJ20: =AVERAGE(T20,X20,AC20,AI20) -> 42.610404 | AK20: =AJ20*K值!M21 -> 41.31531 | AL20: 75 | AM20: 50 | AN20: =AVERAGE(AL20:AM20) -> 62.5 | AP20: =(H20*0.2)+(M20*0.2)+(R20*0.1)+(AK20*0.4)+(AN20*0.1) -> 54.164823
A21: 哈尔滨市 | B21: 1 | C21: 65 | D21: 40 | E21: 60 | F21: 60 | G21: =AVERAGE(C21:F21) -> 56.25 | H21: =G21*K值!M22 -> 56.403941 | I21: 0 | J21: 100 | K21: 25 | L21: 75 | M21: =AVERAGE(I21:L21) -> 50 | N21: 35 | O21: 35 | P21: 35 | Q21: 65 | R21: =AVERAGE(N21:Q21) -> 42.5 | S21: 64.466033 | T21: =AVERAGE(S21) -> 64.466033 | U21: 55.219808 | V21: 77.746109 | W21: 100 | X21: =AVERAGE(U21:W21) -> 77.655305 | Y21: 59.35595 | Z21: 5.2492787 | AA21: 11.021731 | AB21: 46.681283 | AC21: =AVERAGE(Y21:AB21) -> 30.577061 | AD21: 5.2813815 | AE21: 0 | AF21: 64.556962 | AG21: 74.665636 | AH21: 21.692887 | AI21: =AVERAGE(AD21:AH21) -> 33.239373 | AJ21: =AVERAGE(T21,X21,AC21,AI21) -> 51.484443 | AK21: =AJ21*K值!M22 -> 51.625342 | AL21: 25 | AM21: 0 | AN21: =AVERAGE(AL21:AM21) -> 12.5 | AP21: =(H21*0.2)+(M21*0.2)+(R21*0.1)+(AK21*0.4)+(AN21*0.1) -> 47.430925
A22: 南阳市 | B22: 3 | C22: 65 | D22: 100 | E22: 75 | F22: 60 | G22: =AVERAGE(C22:F22) -> 75 | H22: =G22*K值!M23 -> 79.122331 | I22: 50 | J22: 60 | K22: 25 | L22: 50 | M22: =AVERAGE(I22:L22) -> 46.25 | N22: 100 | O22: 35 | P22: 100 | Q22: 65 | R22: =AVERAGE(N22:Q22) -> 75 | S22: 80.861601 | T22: =AVERAGE(S22) -> 80.861601 | U22: 68.072339 | V22: 92.261387 | W22: 100 | X22: =AVERAGE(U22:W22) -> 86.777909 | Y22: 10.289836 | Z22: 2.6371732 | AA22: 5.998221 | AB22: 57.885452 | AC22: =AVERAGE(Y22:AB22) -> 19.20267 | AD22: 11.786063 | AE22: 59.460371 | AF22: 78.481013 | AG22: 58.946555 | AH22: 65.078662 | AI22: =AVERAGE(AD22:AH22) -> 54.750533 | AJ22: =AVERAGE(T22,X22,AC22,AI22) -> 60.398178 | AK22: =AJ22*K值!M23 -> 63.717929 | AL22: 75 | AM22: 0 | AN22: =AVERAGE(AL22:AM22) -> 37.5 | AP22: =(H22*0.2)+(M22*0.2)+(R22*0.1)+(AK22*0.4)+(AN22*0.1) -> 61.811638
A23: 温州市 | B23: 2 | C23: 100 | D23: 100 | E23: 75 | F23: 100 | G23: =AVERAGE(C23:F23) -> 93.75 | H23: =G23*K值!M24 -> 98.902914 | I23: 50 | J23: 60 | K23: 75 | L23: 50 | M23: =AVERAGE(I23:L23) -> 58.75 | N23: 100 | O23: 35 | P23: 100 | Q23: 100 | R23: =AVERAGE(N23:Q23) -> 83.75 | S23: 63.227959 | T23: =AVERAGE(S23) -> 63.227959 | U23: 37.378927 | V23: 51.586031 | W23: 100 | X23: =AVERAGE(U23:W23) -> 62.988319 | Y23: 19.288845 | Z23: 1.425799 | AA23: 37.788792 | AB23: 32.526406 | AC23: =AVERAGE(Y23:AB23) -> 22.757461 | AD23: 50.370965 | AE23: 0 | AF23: 61.181435 | AG23: 19.648852 | AH23: 34.70862 | AI23: =AVERAGE(AD23:AH23) -> 33.181974 | AJ23: =AVERAGE(T23,X23,AC23,AI23) -> 45.538928 | AK23: =AJ23*K值!M24 -> 48.041949 | AL23: 75 | AM23: 0 | AN23: =AVERAGE(AL23:AM23) -> 37.5 | AP23: =(H23*0.2)+(M23*0.2)+(R23*0.1)+(AK23*0.4)+(AN23*0.1) -> 62.872362
A24: 佛山市 | B24: 1 | C24: 65 | D24: 80 | E24: 100 | F24: 60 | G24: =AVERAGE(C24:F24) -> 76.25 | H24: =G24*K值!M25 -> 76.686709 | I24: 0 | J24: 0 | K24: 25 | L24: 25 | M24: =AVERAGE(I24:L24) -> 12.5 | N24: 0 | O24: 65 | P24: 35 | Q24: 0 | R24: =AVERAGE(N24:Q24) -> 25 | S24: 52.726418 | T24: =AVERAGE(S24) -> 52.726418 | U24: 36.808146 | V24: 9.5369019 | W24: 74.596051 | X24: =AVERAGE(U24:W24) -> 40.3137 | Y24: 39.468888 | Z24: NA | AA24: 64.330921 | AB24: 36.100958 | AC24: =AVERAGE(Y24:AB24) -> 46.633589 | AD24: 41.527511 | AE24: 0 | AF24: 65.822785 | AG24: 15.719081 | AH24: 75.925106 | AI24: =AVERAGE(AD24:AH24) -> 39.798897 | AJ24: =AVERAGE(T24,X24,AC24,AI24) -> 44.868151 | AK24: =AJ24*K值!M25 -> 45.125126 | AL24: 0 | AM24: 0 | AN24: =AVERAGE(AL24:AM24) -> 0 | AP24: =(H24*0.2)+(M24*0.2)+(R24*0.1)+(AK24*0.4)+(AN24*0.1) -> 38.387392
A25: 邯郸市 | B25: 2 | C25: 65 | D25: 80 | E25: 60 | F25: 60 | G25: =AVERAGE(C25:F25) -> 66.25 | H25: =G25*K值!M26 -> 69.891393 | I25: 25 | J25: 40 | K25: 25 | L25: 25 | M25: =AVERAGE(I25:L25) -> 28.75 | N25: 0 | O25: 35 | P25: 35 | Q25: 35 | R25: =AVERAGE(N25:Q25) -> 26.25 | S25: 69.290207 | T25: =AVERAGE(S25) -> 69.290207 | U25: 76.562801 | V25: 85.441695 | W25: 100 | X25: =AVERAGE(U25:W25) -> 87.334832 | Y25: 7.5721129 | Z25: 5.202857 | AA25: 12.671242 | AB25: 58.585428 | AC25: =AVERAGE(Y25:AB25) -> 21.00791 | AD25: 15.489094 | AE25: 0 | AF25: 0.42194093 | AG25: 3.9297703 | AH25: 0 | AI25: =AVERAGE(AD25:AH25) -> 3.968161 | AJ25: =AVERAGE(T25,X25,AC25,AI25) -> 45.400277 | AK25: =AJ25*K值!M26 -> 47.895677 | AL25: 25 | AM25: 0 | AN25: =AVERAGE(AL25:AM25) -> 12.5 | AP25: =(H25*0.2)+(M25*0.2)+(R25*0.1)+(AK25*0.4)+(AN25*0.1) -> 42.761549
A26: 宁波市 | B26: 2 | C26: 100 | D26: 100 | E26: 100 | F26: 100 | G26: =AVERAGE(C26:F26) -> 100 | H26: =G26*K值!M27 -> 102.40521 | I26: 75 | J26: 60 | K26: 50 | L26: 75 | M26: =AVERAGE(I26:L26) -> 65 | N26: 100 | O26: 65 | P26: 100 | Q26: 65 | R26: =AVERAGE(N26:Q26) -> 82.5 | S26: 50.14182 | T26: =AVERAGE(S26) -> 50.14182 | U26: 42.312526 | V26: 45.113624 | W26: 100 | X26: =AVERAGE(U26:W26) -> 62.475383 | Y26: 32.628611 | Z26: 18.751465 | AA26: 62.081588 | AB26: 41.43578 | AC26: =AVERAGE(Y26:AB26) -> 38.724361 | AD26: 46.713254 | AE26: 89.190557 | AF26: 10.548523 | AG26: 23.578622 | AH26: 56.401507 | AI26: =AVERAGE(AD26:AH26) -> 45.286493 | AJ26: =AVERAGE(T26,X26,AC26,AI26) -> 49.157014 | AK26: =AJ26*K值!M27 -> 50.339346 | AL26: 75 | AM26: 50 | AN26: =AVERAGE(AL26:AM26) -> 62.5 | AP26: =(H26*0.2)+(M26*0.2)+(R26*0.1)+(AK26*0.4)+(AN26*0.1) -> 68.116781
A27: 潍坊市 | B27: 2 | C27: 65 | D27: 100 | E27: 100 | F27: 100 | G27: =AVERAGE(C27:F27) -> 91.25 | H27: =G27*K值!M28 -> 93.872896 | I27: 50 | J27: 60 | K27: 25 | L27: 100 | M27: =AVERAGE(I27:L27) -> 58.75 | N27: 65 | O27: 35 | P27: 65 | Q27: 65 | R27: =AVERAGE(N27:Q27) -> 57.5 | S27: 70.919495 | T27: =AVERAGE(S27) -> 70.919495 | U27: 57.045445 | V27: 87.052114 | W27: 100 | X27: =AVERAGE(U27:W27) -> 81.365853 | Y27: 8.5613787 | Z27: 6.1769873 | AA27: 26.692084 | AB27: 43.508656 | AC27: =AVERAGE(Y27:AB27) -> 21.234776 | AD27: 18.647359 | AE27: 0 | AF27: 62.869198 | AG27: 19.648852 | AH27: 23.862176 | AI27: =AVERAGE(AD27:AH27) -> 25.005517 | AJ27: =AVERAGE(T27,X27,AC27,AI27) -> 49.63141 | AK27: =AJ27*K值!M28 -> 51.058019 | AL27: 50 | AM27: 50 | AN27: =AVERAGE(AL27:AM27) -> 50 | AP27: =(H27*0.2)+(M27*0.2)+(R27*0.1)+(AK27*0.4)+(AN27*0.1) -> 61.697787
A28: 合肥市 | B28: 2 | C28: 65 | D28: 80 | E28: 75 | F28: 45 | G28: =AVERAGE(C28:F28) -> 66.25 | H28: =G28*K值!M29 -> 65.851839 | I28: 20 | J28: 40 | K28: 50 | L28: 75 | M28: =AVERAGE(I28:L28) -> 46.25 | N28: 65 | O28: 35 | P28: 65 | Q28: 35 | R28: =AVERAGE(N28:Q28) -> 50 | S28: 40.867702 | T28: =AVERAGE(S28) -> 40.867702 | U28: 40.80938 | V28: 62.213562 | W28: 100 | X28: =AVERAGE(U28:W28) -> 67.674314 | Y28: 39.619668 | Z28: 19.638555 | AA28: 33.140171 | AB28: 30.382979 | AC28: =AVERAGE(Y28:AB28) -> 30.695343 | AD28: 36.181745 | AE28: 0 | AF28: 65.400844 | AG28: 19.648852 | AH28: 23.862176 | AI28: =AVERAGE(AD28:AH28) -> 29.018723 | AJ28: =AVERAGE(T28,X28,AC28,AI28) -> 42.064021 | AK28: =AJ28*K值!M29 -> 41.811216 | AL28: 75 | AM28: 0 | AN28: =AVERAGE(AL28:AM28) -> 37.5 | AP28: =(H28*0.2)+(M28*0.2)+(R28*0.1)+(AK28*0.4)+(AN28*0.1) -> 47.894854
A29: 南京市 | B29: 1 | C29: 100 | D29: 60 | E29: 60 | F29: 75 | G29: =AVERAGE(C29:F29) -> 73.75 | H29: =G29*K值!M30 -> 71.045119 | I29: 20 | J29: 40 | K29: 75 | L29: 100 | M29: =AVERAGE(I29:L29) -> 58.75 | N29: 65 | O29: 65 | P29: 65 | Q29: 100 | R29: =AVERAGE(N29:Q29) -> 73.75 | S29: 8.7235119 | T29: =AVERAGE(S29) -> 8.7235119 | U29: 8.406633 | V29: 21.873198 | W29: 98.884875 | X29: =AVERAGE(U29:W29) -> 43.054902 | Y29: 66.24281 | Z29: 63.919052 | AA29: 68.529675 | AB29: 13.681962 | AC29: =AVERAGE(Y29:AB29) -> 53.093375 | AD29: 47.35022 | AE29: 0 | AF29: 70.042194 | AG29: 11.789311 | AH29: 84.602261 | AI29: =AVERAGE(AD29:AH29) -> 42.756797 | AJ29: =AVERAGE(T29,X29,AC29,AI29) -> 36.907146 | AK29: =AJ29*K值!M30 -> 35.553527 | AL29: 75 | AM29: 75 | AN29: =AVERAGE(AL29:AM29) -> 75 | AP29: =(H29*0.2)+(M29*0.2)+(R29*0.1)+(AK29*0.4)+(AN29*0.1) -> 55.055435
A30: 济南市 | B30: 1 | C30: 65 | D30: 80 | E30: 45 | F30: 100 | G30: =AVERAGE(C30:F30) -> 72.5 | H30: =G30*K值!M31 -> 71.625689 | I30: 50 | J30: 60 | K30: 25 | L30: 50 | M30: =AVERAGE(I30:L30) -> 46.25 | N30: 100 | O30: 35 | P30: 100 | Q30: 65 | R30: =AVERAGE(N30:Q30) -> 75 | S30: 20.690406 | T30: =AVERAGE(S30) -> 20.690406 | U30: 48.057092 | V30: 77.401897 | W30: 100 | X30: =AVERAGE(U30:W30) -> 75.152996 | Y30: 64.370928 | Z30: 3.9483323 | AA30: 29.916127 | AB30: 33.362747 | AC30: =AVERAGE(Y30:AB30) -> 32.899534 | AD30: 31.754236 | AE30: 0 | AF30: 69.198312 | AG30: 15.719081 | AH30: 39.047197 | AI30: =AVERAGE(AD30:AH30) -> 31.143765 | AJ30: =AVERAGE(T30,X30,AC30,AI30) -> 39.971675 | AK30: =AJ30*K值!M31 -> 39.489639 | AL30: 75 | AM30: 0 | AN30: =AVERAGE(AL30:AM30) -> 37.5 | AP30: =(H30*0.2)+(M30*0.2)+(R30*0.1)+(AK30*0.4)+(AN30*0.1) -> 50.620993
A31: 徐州市 | B31: 2 | C31: 65 | D31: 80 | E31: 60 | F31: 60 | G31: =AVERAGE(C31:F31) -> 66.25 | H31: =G31*K值!M32 -> 69.495406 | I31: 0 | J31: 60 | K31: 25 | L31: 0 | M31: =AVERAGE(I31:L31) -> 21.25 | N31: 65 | O31: 0 | P31: 65 | Q31: 65 | R31: =AVERAGE(N31:Q31) -> 48.75 | S31: 72.034827 | T31: =AVERAGE(S31) -> 72.034827 | U31: 65.539558 | V31: 83.696051 | W31: 100 | X31: =AVERAGE(U31:W31) -> 83.078536 | Y31: 23.075514 | Z31: 2.5510174 | AA31: 22.868218 | AB31: 19.984934 | AC31: =AVERAGE(Y31:AB31) -> 17.119921 | AD31: 21.098647 | AE31: 0 | AF31: 53.164557 | AG31: 39.297703 | AH31: 30.370042 | AI31: =AVERAGE(AD31:AH31) -> 28.78619 | AJ31: =AVERAGE(T31,X31,AC31,AI31) -> 50.254869 | AK31: =AJ31*K值!M32 -> 52.716717 | AL31: 25 | AM31: 0 | AN31: =AVERAGE(AL31:AM31) -> 12.5 | AP31: =(H31*0.2)+(M31*0.2)+(R31*0.1)+(AK31*0.4)+(AN31*0.1) -> 45.360768
A32: 沈阳市 | B32: 1 | C32: 65 | D32: 40 | E32: 75 | F32: 60 | G32: =AVERAGE(C32:F32) -> 60 | H32: =G32*K值!M33 -> 58.132445 | I32: 40 | J32: 60 | K32: 75 | L32: 25 | M32: =AVERAGE(I32:L32) -> 50 | N32: 65 | O32: 0 | P32: 100 | Q32: 65 | R32: =AVERAGE(N32:Q32) -> 57.5 | S32: 48.165788 | T32: =AVERAGE(S32) -> 48.165788 | U32: 33.662232 | V32: 58.777594 | W32: 100 | X32: =AVERAGE(U32:W32) -> 64.146608 | Y32: 82.061256 | Z32: 27.838512 | AA32: 12.74622 | AB32: 56.207041 | AC32: =AVERAGE(Y32:AB32) -> 44.713257 | AD32: 13.990754 | AE32: 59.460371 | AF32: 61.181435 | AG32: 11.789311 | AH32: 91.110127 | AI32: =AVERAGE(AD32:AH32) -> 47.5064 | AJ32: =AVERAGE(T32,X32,AC32,AI32) -> 51.133013 | AK32: =AJ32*K值!M33 -> 49.541451 | AL32: 50 | AM32: 25 | AN32: =AVERAGE(AL32:AM32) -> 37.5 | AP32: =(H32*0.2)+(M32*0.2)+(R32*0.1)+(AK32*0.4)+(AN32*0.1) -> 50.94307
A33: 长春市 | B33: 2 | C33: 100 | D33: 60 | E33: 75 | F33: 100 | G33: =AVERAGE(C33:F33) -> 83.75 | H33: =G33*K值!M34 -> 83.384066 | I33: 50 | J33: 40 | K33: 25 | L33: 25 | M33: =AVERAGE(I33:L33) -> 35 | N33: 35 | O33: 35 | P33: 100 | Q33: 65 | R33: =AVERAGE(N33:Q33) -> 58.75 | S33: 65.966953 | T33: =AVERAGE(S33) -> 65.966953 | U33: 62.678906 | V33: 72.404683 | W33: 90.172958 | X33: =AVERAGE(U33:W33) -> 75.085516 | Y33: 57.730465 | Z33: 14.906443 | AA33: 11.321642 | AB33: 32.502212 | AC33: =AVERAGE(Y33:AB33) -> 29.115191 | AD33: 12.989673 | AE33: 14.865093 | AF33: 0 | AG33: 0 | AH33: 23.862176 | AI33: =AVERAGE(AD33:AH33) -> 10.343388 | AJ33: =AVERAGE(T33,X33,AC33,AI33) -> 45.127762 | AK33: =AJ33*K值!M34 -> 44.930582 | AL33: 50 | AM33: 0 | AN33: =AVERAGE(AL33:AM33) -> 25 | AP33: =(H33*0.2)+(M33*0.2)+(R33*0.1)+(AK33*0.4)+(AN33*0.1) -> 50.024046
A34: 周口市 | B34: 3 | C34: 65 | D34: 100 | E34: 30 | F34: 75 | G34: =AVERAGE(C34:F34) -> 67.5 | H34: =G34*K值!M35 -> 71.210098 | I34: 50 | J34: 60 | K34: 25 | L34: 50 | M34: =AVERAGE(I34:L34) -> 46.25 | N34: 100 | O34: 100 | P34: 100 | Q34: 35 | R34: =AVERAGE(N34:Q34) -> 83.75 | S34: 85.13707 | T34: =AVERAGE(S34) -> 85.13707 | U34: 82.066925 | V34: 79.500973 | W34: 97.90914 | X34: =AVERAGE(U34:W34) -> 86.492346 | Y34: 3.9533858 | Z34: 2.2364379 | AA34: 5.7732877 | AB34: 47.994738 | AC34: =AVERAGE(Y34:AB34) -> 14.989462 | AD34: 9.0956779 | AE34: 0 | AF34: 49.367089 | AG34: 31.438163 | AH34: 10.846444 | AI34: =AVERAGE(AD34:AH34) -> 20.149475 | AJ34: =AVERAGE(T34,X34,AC34,AI34) -> 51.692088 | AK34: =AJ34*K值!M35 -> 54.533314 | AL34: 50 | AM34: 50 | AN34: =AVERAGE(AL34:AM34) -> 50 | AP34: =(H34*0.2)+(M34*0.2)+(R34*0.1)+(AK34*0.4)+(AN34*0.1) -> 58.680345
A35: 赣州市 | B35: 2 | C35: 100 | D35: 100 | E35: 75 | F35: 75 | G35: =AVERAGE(C35:F35) -> 87.5 | H35: =G35*K值!M36 -> 92.241373 | I35: 50 | J35: 60 | K35: 50 | L35: 50 | M35: =AVERAGE(I35:L35) -> 52.5 | N35: 65 | O35: 65 | P35: 100 | Q35: 65 | R35: =AVERAGE(N35:Q35) -> 73.75 | S35: 79.172015 | T35: =AVERAGE(S35) -> 79.172015 | U35: 68.410112 | V35: 59.281618 | W35: 98.292464 | X35: =AVERAGE(U35:W35) -> 75.328065 | Y35: 4.999041 | Z35: 1.7894114 | AA35: 29.916127 | AB35: 45.53236 | AC35: =AVERAGE(Y35:AB35) -> 20.559235 | AD35: 8.5118442 | AE35: 0 | AF35: 67.932489 | AG35: 3.9297703 | AH35: 15.185021 | AI35: =AVERAGE(AD35:AH35) -> 19.111825 | AJ35: =AVERAGE(T35,X35,AC35,AI35) -> 48.542785 | AK35: =AJ35*K值!M36 -> 51.173179 | AL35: 50 | AM35: 0 | AN35: =AVERAGE(AL35:AM35) -> 25 | AP35: =(H35*0.2)+(M35*0.2)+(R35*0.1)+(AK35*0.4)+(AN35*0.1) -> 59.292546
A36: 菏泽市 | B36: 3 | C36: 65 | D36: 40 | E36: 60 | F36: 45 | G36: =AVERAGE(C36:F36) -> 52.5 | H36: =G36*K值!M37 -> 55.385632 | I36: 25 | J36: 40 | K36: 50 | L36: 50 | M36: =AVERAGE(I36:L36) -> 41.25 | N36: 35 | O36: 0 | P36: 65 | Q36: 65 | R36: =AVERAGE(N36:Q36) -> 41.25 | S36: 81.569712 | T36: =AVERAGE(S36) -> 81.569712 | U36: 72.166538 | V36: 78.84943 | W36: 66.615936 | X36: =AVERAGE(U36:W36) -> 72.543968 | Y36: 5.1449179 | Z36: NA | AA36: 7.4977763 | AB36: 40.394952 | AC36: =AVERAGE(Y36:AB36) -> 17.679216 | AD36: 23.487427 | AE36: 0 | AF36: 40.506329 | AG36: 23.578622 | AH36: 13.015732 | AI36: =AVERAGE(AD36:AH36) -> 20.117622 | AJ36: =AVERAGE(T36,X36,AC36,AI36) -> 47.977629 | AK36: =AJ36*K值!M37 -> 50.614692 | AL36: 0 | AM36: 0 | AN36: =AVERAGE(AL36:AM36) -> 0 | AP36: =(H36*0.2)+(M36*0.2)+(R36*0.1)+(AK36*0.4)+(AN36*0.1) -> 43.698003
A37: 泉州市 | B37: 2 | C37: 65 | D37: 100 | E37: 100 | F37: 45 | G37: =AVERAGE(C37:F37) -> 77.5 | H37: =G37*K值!M38 -> 81.759742 | I37: 0 | J37: 40 | K37: 0 | L37: 0 | M37: =AVERAGE(I37:L37) -> 10 | N37: 35 | O37: 35 | P37: 65 | Q37: 35 | R37: =AVERAGE(N37:Q37) -> 42.5 | S37: 72.984323 | T37: =AVERAGE(S37) -> 72.984323 | U37: 51.761341 | V37: 39.237441 | W37: 98.95457 | X37: =AVERAGE(U37:W37) -> 63.317784 | Y37: 6.3241914 | Z37: 2.2430312 | AA37: 40.038125 | AB37: 27.011092 | AC37: =AVERAGE(Y37:AB37) -> 18.90411 | AD37: 20.082252 | AE37: 14.865093 | AF37: 61.181435 | AG37: 23.578622 | AH37: 100 | AI37: =AVERAGE(AD37:AH37) -> 43.94148 | AJ37: =AVERAGE(T37,X37,AC37,AI37) -> 49.786924 | AK37: =AJ37*K值!M38 -> 52.523434 | AL37: 50 | AM37: 0 | AN37: =AVERAGE(AL37:AM37) -> 25 | AP37: =(H37*0.2)+(M37*0.2)+(R37*0.1)+(AK37*0.4)+(AN37*0.1) -> 46.111322
A38: 南宁市 | B38: 2 | C38: 100 | D38: 60 | E38: 60 | F38: 100 | G38: =AVERAGE(C38:F38) -> 80 | H38: =G38*K值!M39 -> 80.630979 | I38: 20 | J38: 40 | K38: 25 | L38: 50 | M38: =AVERAGE(I38:L38) -> 33.75 | N38: 65 | O38: 65 | P38: 100 | Q38: 65 | R38: =AVERAGE(N38:Q38) -> 73.75 | S38: 82.12555 | T38: =AVERAGE(S38) -> 82.12555 | U38: 99.885955 | V38: 25.401366 | W38: 99.790914 | X38: =AVERAGE(U38:W38) -> 75.026078 | Y38: 23.670055 | Z38: 20.943099 | AA38: 31.115772 | AB38: 1.0613066 | AC38: =AVERAGE(Y38:AB38) -> 19.197558 | AD38: 39.757882 | AE38: 0 | AF38: 0.84388186 | AG38: 3.9297703 | AH38: 91.110127 | AI38: =AVERAGE(AD38:AH38) -> 27.128332 | AJ38: =AVERAGE(T38,X38,AC38,AI38) -> 50.86938 | AK38: =AJ38*K值!M39 -> 51.270598 | AL38: 50 | AM38: 50 | AN38: =AVERAGE(AL38:AM38) -> 50 | AP38: =(H38*0.2)+(M38*0.2)+(R38*0.1)+(AK38*0.4)+(AN38*0.1) -> 55.759435
A39: 昆明市 | B39: 1 | C39: 65 | D39: 40 | E39: 60 | F39: 60 | G39: =AVERAGE(C39:F39) -> 56.25 | H39: =G39*K值!M40 -> 59.341748 | I39: 100 | J39: 40 | K39: 75 | L39: 75 | M39: =AVERAGE(I39:L39) -> 72.5 | N39: 65 | O39: 65 | P39: 100 | Q39: 65 | R39: =AVERAGE(N39:Q39) -> 73.75 | S39: 63.502096 | T39: =AVERAGE(S39) -> 63.502096 | U39: 45.210059 | V39: 68.590696 | W39: 87.141211 | X39: =AVERAGE(U39:W39) -> 66.980655 | Y39: 53.180088 | Z39: 14.906443 | AA39: 39.363326 | AB39: 35.893114 | AC39: =AVERAGE(Y39:AB39) -> 35.835742 | AD39: 26.873849 | AE39: 59.460371 | AF39: 14.345992 | AG39: 19.648852 | AH39: 34.70862 | AI39: =AVERAGE(AD39:AH39) -> 31.007537 | AJ39: =AVERAGE(T39,X39,AC39,AI39) -> 49.331508 | AK39: =AJ39*K值!M40 -> 52.042985 | AL39: 50 | AM39: 0 | AN39: =AVERAGE(AL39:AM39) -> 25 | AP39: =(H39*0.2)+(M39*0.2)+(R39*0.1)+(AK39*0.4)+(AN39*0.1) -> 57.060544
A40: 济宁市 | B40: 2 | C40: 65 | D40: 100 | E40: 100 | F40: 100 | G40: =AVERAGE(C40:F40) -> 91.25 | H40: =G40*K值!M41 -> 96.265503 | I40: 50 | J40: 40 | K40: 25 | L40: 50 | M40: =AVERAGE(I40:L40) -> 41.25 | N40: 100 | O40: 35 | P40: 100 | Q40: 100 | R40: =AVERAGE(N40:Q40) -> 83.75 | S40: 69.726713 | T40: =AVERAGE(S40) -> 69.726713 | U40: 63.714859 | V40: 86.225391 | W40: 96.480386 | X40: =AVERAGE(U40:W40) -> 82.140212 | Y40: 6.60859 | Z40: 0.6187142 | AA40: 18.44453 | AB40: 28.133066 | AC40: =AVERAGE(Y40:AB40) -> 13.451225 | AD40: 34.655902 | AE40: 0 | AF40: 70.042194 | AG40: 3.9297703 | AH40: 17.35431 | AI40: =AVERAGE(AD40:AH40) -> 25.196435 | AJ40: =AVERAGE(T40,X40,AC40,AI40) -> 47.628646 | AK40: =AJ40*K值!M41 -> 50.246527 | AL40: 50 | AM40: 0 | AN40: =AVERAGE(AL40:AM40) -> 25 | AP40: =(H40*0.2)+(M40*0.2)+(R40*0.1)+(AK40*0.4)+(AN40*0.1) -> 58.476711
...

Sheet K值
A1: 城市特征指标值数据收集表（暂以2020年为基准）
A2: 城市 | B2: 居民Po | C2: 按ln值
B3: 平均受教育年限（15岁以上）（年） | C3: ln(k) | D3: Median | E3: 均值 | F3: 方差 | G3: μ+σ | H3: max | I3: μ-σ | J3: min | K3: 最大值 | L3: 最小值 | M3: 最终修正系数
A4: 重庆市 | B4: =VLOOKUP(A4,'[1]统计年鉴数据-徐 '!$A:$H,8,0) -> 9.47 | C4: =LN(B4) -> 2.2481289 | D4: =MEDIAN(C4:C299) -> 2.3267754 | E4: =AVERAGE(C4:C299) -> 2.3104554 | F4: =STDEVP(C4:C299) -> 0.10490668 | G4: =E4+F4 -> 2.415362 | H4: =MAX(C4:C299) -> 2.5022553 | I4: =E4-F4 -> 2.2055487 | J4: =MIN(C4:C299) -> 2.0955609 | K4: =MIN(G4:H4) -> 2.415362 | L4: =MAX(I4:J4) -> 2.2055487 | M4: =IF(AND(L$4<=C4, C4<=K$4),D$4/C4,IF(C4>=K$4,D$4/K$4,D$4/L$4)) -> 1.0349831
A5: 上海市 | B5: =VLOOKUP(A5,'[1]统计年鉴数据-徐 '!$A:$H,8,0) -> 11.5 | C5: =LN(B5) -> 2.442347 | M5: =IF(AND(L$4<=C5, C5<=K$4),D$4/C5,IF(C5>=K$4,D$4/K$4,D$4/L$4)) -> 0.96332365
A6: 北京市 | B6: =VLOOKUP(A6,'[1]统计年鉴数据-徐 '!$A:$H,8,0) -> 12.21 | C6: =LN(B6) -> 2.5022553 | M6: =IF(AND(L$4<=C6, C6<=K$4),D$4/C6,IF(C6>=K$4,D$4/K$4,D$4/L$4)) -> 0.96332365
A7: 成都市 | B7: =VLOOKUP(A7,'[1]统计年鉴数据-徐 '!$A:$H,8,0) -> 10.51 | C7: =LN(B7) -> 2.3523272 | M7: =IF(AND(L$4<=C7, C7<=K$4),D$4/C7,IF(C7>=K$4,D$4/K$4,D$4/L$4)) -> 0.98913764
A8: 广州市 | B8: =VLOOKUP(A8,'[1]统计年鉴数据-徐 '!$A:$H,8,0) -> 11.2 | C8: =LN(B8) -> 2.4159138 | M8: =IF(AND(L$4<=C8, C8<=K$4),D$4/C8,IF(C8>=K$4,D$4/K$4,D$4/L$4)) -> 0.96332365
A9: 深圳市 | B9: =VLOOKUP(A9,'[1]统计年鉴数据-徐 '!$A:$H,8,0) -> 11.38 | C9: =LN(B9) -> 2.4318574 | M9: =IF(AND(L$4<=C9, C9<=K$4),D$4/C9,IF(C9>=K$4,D$4/K$4,D$4/L$4)) -> 0.96332365
A10: 天津市 | B10: =VLOOKUP(A10,'[1]统计年鉴数据-徐 '!$A:$H,8,0) -> 10.87 | C10: =LN(B10) -> 2.3860067 | M10: =IF(AND(L$4<=C10, C10<=K$4),D$4/C10,IF(C10>=K$4,D$4/K$4,D$4/L$4)) -> 0.97517554
A11: 苏州市 | B11: =VLOOKUP(A11,'[1]统计年鉴数据-徐 '!$A:$H,8,0) -> 10.3 | C11: =LN(B11) -> 2.3321439 | M11: =IF(AND(L$4<=C11, C11<=K$4),D$4/C11,IF(C11>=K$4,D$4/K$4,D$4/L$4)) -> 0.99769803
A12: 郑州市 | B12: =VLOOKUP(A12,'[1]统计年鉴数据-徐 '!$A:$H,8,0) -> 11.11 | C12: =LN(B12) -> 2.4078456 | M12: =IF(AND(L$4<=C12, C12<=K$4),D$4/C12,IF(C12>=K$4,D$4/K$4,D$4/L$4)) -> 0.9663308
A13: 武汉市 | B13: =VLOOKUP(A13,'[1]统计年鉴数据-徐 '!$A:$H,8,0) -> 11.54 | C13: =LN(B13) -> 2.4458193 | M13: =IF(AND(L$4<=C13, C13<=K$4),D$4/C13,IF(C13>=K$4,D$4/K$4,D$4/L$4)) -> 0.96332365
A14: 西安市 | B14: =VLOOKUP(A14,'[1]统计年鉴数据-徐 '!$A:$H,8,0) -> 11.38 | C14: =LN(B14) -> 2.4318574 | M14: =IF(AND(L$4<=C14, C14<=K$4),D$4/C14,IF(C14>=K$4,D$4/K$4,D$4/L$4)) -> 0.96332365
A15: 杭州市 | B15: =VLOOKUP(A15,'[1]统计年鉴数据-徐 '!$A:$H,8,0) -> 10.76 | C15: =LN(B15) -> 2.3758356 | M15: =IF(AND(L$4<=C15, C15<=K$4),D$4/C15,IF(C15>=K$4,D$4/K$4,D$4/L$4)) -> 0.97935035
A16: 保定市 | B16: =VLOOKUP(A16,'[1]统计年鉴数据-徐 '!$A:$H,8,0) -> 9.19 | C16: =LN(B16) -> 2.2181159 | M16: =IF(AND(L$4<=C16, C16<=K$4),D$4/C16,IF(C16>=K$4,D$4/K$4,D$4/L$4)) -> 1.0489873
... A39: 南宁市 | B39: =VLOOKUP(A39,'[1]统计年鉴数据-徐 '!$A:$H,8,0) -> 10.06 | C39: =LN(B39) -> 2.3085672 | M39: =IF(AND(L$4<=C39, C39<=K$4),D$4/C39,IF(C39>=K$4,D$4/K$4,D$4/L$4)) -> 1.0078872
A40: 昆明市 | B40: =VLOOKUP(A40,'[1]统计年鉴数据-徐 '!$A:$H,8,0) -> 10.22 | M40: =IF(AND(L$4<=C40, C40<=K$4),D$4/C40,IF(C40>=K$4,D$4/K$4,D$4/L$4)) -> 1.0549644
A41: 济宁市 | B41: =VLOOKUP(A41,'[1]统计年鉴数据-徐 '!$A:$H,8,0) -> 8.97 | M41: =IF(AND(L$4<=C41, C41<=K$4),D$4/C41,IF(C41>=K$4,D$4/K$4,D$4/L$4)) -> 1.0549644
A42: 福州市 | B42: =VLOOKUP(A42,'[1]统计年鉴数据-徐 '!$A:$H,8,0) -> 9.95 | M42: =IF(AND(L$4<=C42, C42<=K$4),D$4/C42,IF(C42>=K$4,D$4/K$4,D$4/L$4)) -> 1.0549644
A43: 阜阳市 | B43: =VLOOKUP(A43,'[1]统计年鉴数据-徐 '!$A:$H,8,0) -> 8.18 | M43: =IF(AND(L$4<=C43, C43<=K$4),D$4/C43,IF(C43>=K$4,D$4/K$4,D$4/L$4)) -> 1.0549644
A44: 商丘市 | B44: =VLOOKUP(A44,'[1]统计年鉴数据-徐 '!$A:$H,8,0) -> 8.59 | M44: =IF(AND(L$4<=C44, C44<=K$4),D$4/C44,IF(C44>=K$4,D$4/K$4,D$4/L$4)) -> 1.0549644
A45: 南通市 | B45: =VLOOKUP(A45,'[1]统计年鉴数据-徐 '!$A:$H,8,0) -> 9.43 | M45: =IF(AND(L$4<=C45, C45<=K$4),D$4/C45,IF(C45>=K$4,D$4/K$4,D$4/L$4)) -> 1.0549644
A46: 唐山市 | B46: =VLOOKUP(A46,'[1]统计年鉴数据-徐 '!$A:$H,8,0) -> 9.67 | M46: =IF(AND(L$4<=C46, C46<=K$4),D$4/C46,IF(C46>=K$4,D$4/K$4,D$4/L$4)) -> 1.0549644
A47: 无锡市 | B47: =VLOOKUP(A47,'[1]统计年鉴数据-徐 '!$A:$H,8,0) -> 10.39 | M47: =IF(AND(L$4<=C47, C47<=K$4),D$4/C47,IF(C47>=K$4,D$4/K$4,D$4/L$4)) -> 1.0549644
A48: 大连市 | B48: =VLOOKUP(A48,'[1]统计年鉴数据-徐 '!$A:$H,8,0) -> 10.49 | M48: =IF(AND(L$4<=C48, C48<=K$4),D$4/C48,IF(C48>=K$4,D$4/K$4,D$4/L$4)) -> 1.0549644
A49: 沧州市 | B49: =VLOOKUP(A49,'[1]统计年鉴数据-徐 '!$A:$H,8,0) -> 8.88 | M49: =IF(AND(L$4<=C49, C49<=K$4),D$4/C49,IF(C49>=K$4,D$4/K$4,D$4/L$4)) -> 1.0549644
A50: 邢台市 | B50: =VLOOKUP(A50,'[1]统计年鉴数据-徐 '!$A:$H,8,0) -> 8.84 | M50: =IF(AND(L$4<=C50, C50<=K$4),D$4/C50,IF(C50>=K$4,D$4/K$4,D$4/L$4)) -> 1.0549644
A51: 烟台市 | B51: =VLOOKUP(A51,'[1]统计年鉴数据-徐 '!$A:$H,8,0) -> 10.01 | M51: =IF(AND(L$4<=C51, C51<=K$4),D$4/C51,IF(C51>=K$4,D$4/K$4,D$4/L$4)) -> 1.0549644
... A299: 林芝市 | B299: =VLOOKUP(A299,'[1]统计年鉴数据-徐 '!$A:$H,8,0) -> 7.73 | M299: =IF(AND(L$4<=C299, C299<=K$4),D$4/C299,IF(C299>=K$4,D$4/K$4,D$4/L$4)) -> 1.0549644

Sheet 城市分组
A1: 城市 | B1: 分组 | D1: 城市 | E1: 分组
A2: 重庆市 | B2: 1 | D2: 重庆市 | E2: {=INDEX(B2:B298, MATCH(D2:D297,A2:A298,0))} -> 1
A3: 成都市 | B3: 1 | D3: 上海市 | E3: 1
A4: 上海市 | B4: 1 | D4: 北京市 | E4: 1
A5: 北京市 | B5: 1 | D5: 成都市 | E5: 1
A6: 周口市 | B6: 3 | D6: 广州市 | E6: 1
A7: 南阳市 | B7: 3 | D7: 深圳市 | E7: 1
A8: 保定市 | B8: 2 | D8: 天津市 | E8: 1
A9: 临沂市 | B9: 2 | D9: 苏州市 | E9: 2
A10: 天津市 | B10: 1 | D10: 郑州市 | E10: 1
A11: 阜阳市 | B11: 3 | D11: 武汉市 | E11: 1
A12: 邯郸市 | B12: 2 | D12: 西安市 | E12: 1
A13: 石家庄市 | B13: 2 | D13: 杭州市 | E13: 1
A14: 徐州市 | B14: 2 | D14: 保定市 | E14: 2
... A297: 吐鲁番市 | B297: 4 | D297: 林芝市 | E297: 4
A298: 哈密市 | B298: 4

Sheet Sheet1
A1: 得分 城市 | B1: 城市分类 | C1: P | E1: 得分 城市 | F1: 城市分类 | G1: I | I1: 得分 城市 | J1: 城市分类 | K1: C | M1: 得分 城市 | N1: 城市分类 | O1: O | Q1: 得分 城市 | R1: 城市分类 | S1: F | V1: 得分 城市 | W1: 城市分类
A2: 天津市 | B2: 1 | C2: 97.517554 | E2: 北京市 | F2: 1 | G2: 82.5 | I2: 北京市 | J2: 1 | K2: 91.25 | M2: 北京市 | N2: 1 | O2: 58.758562 | Q2: 北京市 | R2: 1 | S2: 87.5 | V2: 乌鲁木齐市 | W2: 2 | X2: #DIV/0!
A3: 深圳市 | B3: 1 | C3: 87.903283 | E3: 杭州市 | F3: 1 | G3: 76.25 | I3: 深圳市 | J3: 1 | K3: 91.25 | M3: 大连市 | N3: 1 | O3: 55.069527 | Q3: 成都市 | R3: 1 | S3: 87.5 | V3: 普洱市 | W3: 4 | X3: #N/A
A4: 东莞市 | B4: 1 | C4: 85.633561 | E4: 成都市 | F4: 1 | G4: 68.75 | I4: 西安市 | J4: 1 | K4: 91.25 | M4: 重庆市 | N4: 1 | O4: 54.826994 | Q4: 重庆市 | R4: 1 | S4: 50 | V4: 资阳市 | W4: 4 | X4: #N/A
A5: 上海市 | B5: 1 | C5: 85.494974 | E5: 昆明市 | F5: 1 | G5: 66.25 | I5: 杭州市 | J5: 1 | K5: 83.75 | M5: 哈尔滨市 | N5: 1 | O5: 53.708488 | Q5: 上海市 | R5: 1 | S5: 50 | V5: 北京市 | W5: 1 | X5: 65.041603
A6: 成都市 | B6: 1 | C6: 85.313122 | E6: 深圳市 | F6: 1 | G6: 58.75 | I6: 上海市 | J6: 1 | K6: 82.5 | M6: 上海市 | N6: 1 | O6: 52.32033 | Q6: 广州市 | R6: 1 | S6: 50 | V6: 金华市 | W6: 3 | X6: 62.288131
A7: 北京市 | B7: 1 | C7: 84.290819 | E7: 上海市 | F7: 1 | G7: 56.25 | I7: 成都市 | J7: 1 | K7: 82.5 | M7: 昆明市 | N7: 1 | O7: 52.042985 | Q7: 天津市 | R7: 1 | S7: 50 | V7: 湖州市 | W7: 3 | X7: 60.605492
A8: 大连市 | B8: 1 | C8: 83.078448 | E8: 广州市 | F8: 1 | G8: 51.25 | I8: 武汉市 | J8: 1 | K8: 75 | M8: 郑州市 | N8: 1 | O8: 51.952445 | Q8: 郑州市 | R8: 1 | S8: 50 | V8: 广安市 | W8: 4 | X8: 59.360329
A9: 重庆市 | B9: 1 | C9: 82.798646 | E9: 武汉市 | F9: 1 | G9: 50 | I9: 济南市 | J9: 1 | K9: 75 | M9: 东莞市 | N9: 1 | O9: 51.188441 | Q9: 武汉市 | R9: 1 | S9: 50 | V9: 铜陵市 | W9: 3 | X9: 58.874907
A10: 杭州市 | B10: 1 | C10: 80.796403 | E10: 天津市 | F10: 1 | G10: 46.25 | I10: 青岛市 | J10: 1 | K10: 73.75 | M10: 杭州市 | N10: 1 | O10: 50.616432 | Q10: 东莞市 | R10: 1 | S10: 50 | V10: 襄阳市 | W10: 2 | X10: 58.705802
A11: 武汉市 | B11: 1 | C11: 79.474201 | E11: 济南市 | F11: 1 | G11: 46.25 | I11: 昆明市 | J11: 1 | K11: 73.75 | M11: 沈阳市 | N11: 1 | O11: 49.541451 | Q11: 深圳市 | R11: 1 | S11: 37.5 | V11: 杭州市 | W11: 1 | X11: 58.33
A12: 广州市 | B12: 1 | C12: 78.270046 | E12: 哈尔滨市 | F12: 1 | G12: 43.75 | I12: 广州市 | J12: 1 | K12: 58.75 | M12: 青岛市 | N12: 1 | O12: 48.519001 | Q12: 南京市 | R12: 1 | S12: 37.5 | V12: 吉林市 | W12: 2 | X12: 57.894905
A13: 长沙市 | B13: 1 | C13: 77.568494 | E13: 青岛市 | F13: 1 | G13: 41.25 | I13: 郑州市 | J13: 1 | K13: 58.75 | M13: 佛山市 | N13: 1 | O13: 47.626803 | Q13: 济南市 | R13: 1 | S13: 37.5 | V13: 温州市 | W13: 2 | X13: 57.872507
A14: 佛山市 | B14: 1 | C14: 76.686709 | E14: 长沙市 | F14: 1 | G14: 41.25 | I14: 天津市 | J14: 1 | K14: 57.5 | M14: 西安市 | N14: 1 | O14: 44.113102 | Q14: 西安市 | R14: 1 | S14: 25 | V14: 中山市 | W14: 2 | X14: 57.714603
A15: 青岛市 | B15: 1 | C15: 75.667531 | E15: 东莞市 | F15: 1 | G15: 33.75 | I15: 沈阳市 | J15: 1 | K15: 57.5 | M15: 长沙市 | N15: 1 | O15: 43.681611 | Q15: 杭州市 | R15: 1 | S15: 25 | V15: 宁波市 | W15: 2 | X15: 57.366781
A16: 西安市 | B16: 1 | C16: 74.657583 | E16: 郑州市 | F16: 1 | G16: 28.75 | I16: 东莞市 | J16: 1 | K16: 51.25 | M16: 武汉市 | N16: 1 | O16: 42.651165 | Q16: 青岛市 | R16: 1 | S16: 25 | V16: 南阳市 | W16: 3 | X16: 57.186638
... A22: 哈尔滨市 | B22: 1 | C22: 56.403941 | E22: 大连市 | F22: 1 | G22: 6.25 | I22: 大连市 | J22: 1 | K22: 8.75 | M22: 广州市 | N22: 1 | O22: 31.157836 | Q22: 佛山市 | R22: 1 | S22: 0 | V22: 丽水市 | W22: 4 | X22: 56.003249
A23: 淄博市 | B23: 2 | C23: 105.49644 | E23: 吉林市 | F23: 2 | G23: 81.25 | I23: 吉林市 | J23: 2 | K23: 100 | M23: 乌鲁木齐市 | N23: 2 | O23: #DIV/0! | Q23: 福州市 | R23: 2 | S23: 62.5 | V23: 鹰潭市 | W23: 4 | X23: 55.889069
A24: 柳州市 | B24: 2 | C24: 105.49644 | E24: 襄阳市 | F24: 2 | G24: 75 | I24: 临沂市 | J24: 2 | K24: 91.25 | M24: 临沂市 | N24: 2 | O24: 62.029623 | Q24: 赤峰市 | R24: 2 | S24: 62.5 | V24: 武威市 | W24: 4 | X24: 55.879585
A25: 宁波市 | B25: 2 | C25: 102.40521 | E25: 十堰市 | F25: 2 | G25: 75 | I25: 温州市 | J25: 2 | K25: 83.75 | M25: 中山市 | N25: 2 | O25: 59.934783 | Q25: 石家庄市 | R25: 2 | S25: 50 | V25: 商丘市 | W25: 3 | X25: 55.649573
A26: 温州市 | B26: 2 | C26: 98.902914 | E26: 银川市 | F26: 2 | G26: 68.75 | I26: 济宁市 | J26: 2 | K26: 83.75 | M26: 唐山市 | N26: 2 | O26: 57.72341 | Q26: 潍坊市 | R26: 2 | S26: 50 | V26: 晋中市 | W26: 3 | X26: 55.487764
A27: 南昌市 | B27: 2 | C27: 98.902914 | E27: 扬州市 | F27: 2 | G27: 65 | I27: 大同市 | J27: 2 | K27: 83.75 | M27: 烟台市 | N27: 2 | O27: 56.357137 | Q27: 无锡市 | R27: 2 | S27: 50 | V27: 阜阳市 | W27: 3 | X27: 55.299305
A28: 济宁市 | B28: 2 | C28: 96.265503 | E28: 温州市 | F28: 2 | G28: 58.75 | I28: 宁波市 | J28: 2 | K28: 82.5 | M28: 桂林市 | N28: 2 | O28: 55.403703 | Q28: 邢台市 | R28: 2 | S28: 50 | V28: 潍坊市 | W28: 2 | X28: 55.215894
A29: 惠州市 | B29: 2 | C29: 96.265503 | E29: 芜湖市 | F29: 2 | G29: 58.75 | I29: 绵阳市 | J29: 2 | K29: 82.5 | M29: 襄阳市 | N29: 2 | O29: 54.881752 | Q29: 湛江市 | R29: 2 | S29: 50 | V29: 济宁市 | W29: 2 | X29: 55.016245
A30: 聊城市 | B30: 2 | C30: 96.265503 | E30: 大同市 | F30: 2 | G30: 58.75 | I30: 中山市 | J30: 2 | K30: 82.5 | M30: 徐州市 | N30: 2 | O30: 54.603989 | Q30: 上饶市 | R30: 2 | S30: 50 | V30: 威海市 | W30: 3 | X30: 54.967143
A31: 襄阳市 | B31: 2 | C31: 96.265503 | E31: 呼和浩特市 | F31: 2 | G31: 57.5 | I31: 宜昌市 | J31: 2 | K31: 82.5 | M31: 邢台市 | N31: 2 | O31: 54.218192 | Q31: 惠州市 | R31: 2 | S31: 50 | V31: 十堰市 | W31: 2 | X31: 54.675517
A32: 扬州市 | B32: 2 | C32: 96.265503 | E32: 西宁市 | F32: 2 | G32: 56.25 | I32: 芜湖市 | J32: 2 | K32: 82.5 | M32: 莆田市 | N32: 2 | O32: 53.811746 | Q32: 贵阳市 | R32: 2 | S32: 50 | V32: 吉安市 | W32: 4 | X32: 54.604249
A33: 十堰市 | B33: 2 | C33: 96.265503 | E33: 福州市 | F33: 2 | G33: 53.75 | I33: 聊城市 | J33: 2 | K33: 75 | M33: 枣庄市 | N33: 2 | O33: 53.787989 | Q33: 绍兴市 | R33: 2 | S33: 50 | V33: 周口市 | W33: 3 | X33: 54.58677
A34: 石家庄市 | B34: 2 | C34: 95.219699 | E34: 赣州市 | F34: 2 | G34: 52.5 | I34: 太原市 | J34: 2 | K34: 75 | M34: 台州市 | N34: 2 | O34: 53.651676 | Q34: 中山市 | R34: 2 | S34: 50 | V34: 赣州市 | W34: 2 | X34: 54.546232
A35: 潍坊市 | B35: 2 | C35: 93.872896 | E35: 烟台市 | F35: 2 | G35: 52.5 | I35: 襄阳市 | J35: 2 | K35: 75 | M35: 保定市 | N35: 2 | O35: 53.648589 | Q35: 芜湖市 | R35: 2 | S35: 50 | V35: 绍兴市 | W35: 2 | X35: 54.296393
... A213: 漯河市 | B213: 3 | C213: 14.505761 | E213: 鸡西市 | F213: 3 | G213: 10 | I213: 鸡西市 | J213: 3 | K213: 8.75 | M213: 北海市 | N213: 3 | O213: 28.894966 | Q213: 萍乡市 | R213: 3 | S213: 0 | V213: 白山市 | W213: 4 | X213: 41.584305
A214: 石嘴山市 | B214: 4 | C214: 105.49644 | E214: 普洱市 | F214: 4 | G214: #N/A | I214: 普洱市 | J214: 4 | K214: #N/A | M214: 武威市 | N214: 4 | O214: 59.550475 | Q214: 普洱市 | R214: 4 | S214: #N/A | V214: 江门市 | W214: 2 | X214: 41.493812
A215: 七台河市 | B215: 4 | C215: 98.902914 | E215: 资阳市 | F215: 4 | G215: #N/A | I215: 资阳市 | J215: 4 | K215: #N/A | M215: 丽水市 | N215: 4 | O215: 58.637336 | Q215: 资阳市 | R215: 4 | S215: #N/A | V215: 德阳市 | W215: 3 | X215: 41.474545
A216: 金昌市 | B216: 4 | C216: 98.902914 | E216: 安康市 | F216: 4 | G216: 65 | I216: 广安市 | J216: 4 | K216: 100 | M216: 临沧市 | N216: 4 | O216: 58.232252 | Q216: 鹰潭市 | R216: 4 | S216: 62.5 | V216: 池州市 | W216: 4 | X216: 41.444584
A217: 延安市 | B217: 4 | C217: 96.265503 | E217: 随州市 | F217: 4 | G217: 65 | I217: 丽水市 | J217: 4 | K217: 100 | M217: 广安市 | N217: 4 | O217: 58.111599 | Q217: 黄冈市 | R217: 4 | S217: 50 | V217: 大连市 | W217: 1 | X217: 41.3935
A218: 朔州市 | B218: 4 | C218: 96.265503 | E218: 武威市 | F218: 4 | G218: 58.75 | I218: 安康市 | J218: 4 | K218: 91.25 | M218: 七台河市 | N218: 4 | O218: 56.935955 | Q218: 吉安市 | R218: 4 | S218: 50 | V218: 揭阳市 | W218: 3 | X218: 41.356607
A219: 张掖市 | B219: 4 | C219: 96.265503 | E219: 广安市 | F219: 4 | G219: 57.5 | I219: 鹰潭市 | J219: 4 | K219: 75 | M219: 吉安市 | N219: 4 | O219: 56.049636 | Q219: 绥化市 | R219: 4 | S219: 50 | V219: 淮北市 | W219: 3 | X219: 41.265529
A220: 咸宁市 | B220: 4 | C220: 94.946798 | E220: 鹰潭市 | F220: 4 | G220: 53.75 | I220: 嘉峪关市 | J220: 4 | K220: 75 | M220: 定西市 | N220: 4 | O220: 55.42338 | Q220: 南平市 | R220: 4 | S220: 50 | V220: 湘潭市 | W220: 3 | X220: 41.200582
A221: 吉安市 | B221: 4 | C221: 89.671975 | E221: 吕梁市 | F221: 4 | G221: 52.5 | I221: 通辽市 | J221: 4 | K221: 67.5 | M221: 庆阳市 | N221: 4 | O221: 55.327718 | Q221: 丽水市 | R221: 4 | S221: 50 | V221: 南京市 | W221: 1 | X221: 41.08515
A222: 铜仁市 | B222: 4 | C222: 89.671975 | E222: 汕尾市 | F222: 4 | G222: 52.5 | I222: 四平市 | J222: 4 | K222: 67.5 | M222: 三门峡市 | N222: 4 | O222: 54.827775 | Q222: 广元市 | R222: 4 | S222: 50 | V222: 宁德市 | W222: 4 | X222: 41.069921
...

Sheet Sheet2
A1: 城市 | B1: 城市类别 | C1: P（修正后） | D1: 四分位数 | F1: 城市 | G1: 城市类别 | H1: I | K1: 城市 | L1: 城市类别 | M1: C | P1: 城市 | Q1: 城市类别 | R1: O（修正后） | U1: 城市 | V1: 城市类别 | W1: A
A2: 淄博市 | B2: 2 | C2: 105.49644 | D2: =_xlfn.QUARTILE.INC(C2:C297,1) -> 69.891393 | F2: 普洱市 | G2: 4 | H2: #N/A | I2: =_xlfn.QUARTILE.INC(H4:H297,1) -> 21.25 | K2: 普洱市 | L2: 4 | M2: #N/A | N2: =_xlfn.QUARTILE.INC(M4:M297,1) -> 33.75 | P2: 乌鲁木齐市 | Q2: 2 | R2: #DIV/0! | S2: =_xlfn.QUARTILE.INC(R3:R297,1) -> 44.401179 | U2: 普洱市 | V2: 4 | W2: #N/A | X2: =_xlfn.QUARTILE.INC(W4:W297,1) -> 12.5
A3: 柳州市 | B3: 2 | C3: 105.49644 | D3: =_xlfn.QUARTILE.INC(C2:C298,2) -> 80.441037 | F3: 资阳市 | G3: 4 | H3: #N/A | I3: =_xlfn.QUARTILE.INC(H4:H298,2) -> 28.75 | K3: 资阳市 | L3: 4 | M3: #N/A | N3: =_xlfn.QUARTILE.INC(M4:M298,2) -> 50 | P3: 南阳市 | Q3: 3 | R3: 63.717929 | S3: =_xlfn.QUARTILE.INC(R3:R298,2) -> 48.234913 | U3: 资阳市 | V3: 4 | W3: #N/A | X3: =_xlfn.QUARTILE.INC(W4:W298,2) -> 25
A4: 石嘴山市 | B4: 4 | C4: 105.49644 | D4: =_xlfn.QUARTILE.INC(C2:C299,3) -> 88.35327 | F4: 北京市 | G4: 1 | H4: 82.5 | I4: =_xlfn.QUARTILE.INC(H4:H299,3) -> 43.75 | K4: 吉林市 | L4: 2 | M4: 100 | N4: =_xlfn.QUARTILE.INC(M4:M299,3) -> 66.25 | P4: 临沂市 | Q4: 2 | R4: 62.029623 | S4: =_xlfn.QUARTILE.INC(R3:R299,3) -> 51.908248 | U4: 北京市 | V4: 1 | W4: 87.5 | X4: =_xlfn.QUARTILE.INC(W4:W299,3) -> 37.5
A5: 宁波市 | B5: 2 | C5: 102.40521 | D5: =_xlfn.QUARTILE.INC(C3:C300,4) -> 105.49644 | F5: 吉林市 | G5: 2 | H5: 81.25 | I5: =_xlfn.QUARTILE.INC(H4:H300,4) -> 82.5 | K5: 广安市 | L5: 4 | M5: 100 | N5: =_xlfn.QUARTILE.INC(M4:M300,4) -> 100 | P5: 晋中市 | Q5: 3 | R5: 60.133423 | S5: =_xlfn.QUARTILE.INC(R3:R300,4) -> 63.717929 | U5: 成都市 | V5: 1 | W5: 87.5 | X5: =_xlfn.QUARTILE.INC(W4:W300,4) -> 87.5
A6: 温州市 | B6: 2 | C6: 98.902914 | F6: 杭州市 | G6: 1 | H6: 76.25 | K6: 丽水市 | L6: 4 | M6: 100 | P6: 中山市 | Q6: 2 | R6: 59.934783 | U6: 湖州市 | V6: 3 | W6: 75
A7: 商丘市 | B7: 3 | C7: 98.902914 | F7: 襄阳市 | G7: 2 | H7: 75 | K7: 铜陵市 | L7: 3 | M7: 100 | P7: 武威市 | Q7: 4 | R7: 59.550475 | U7: 福州市 | V7: 2 | W7: 62.5
A8: 金华市 | B8: 3 | C8: 98.902914 | F8: 十堰市 | G8: 2 | H8: 75 | K8: 北京市 | L8: 1 | M8: 91.25 | P8: 北京市 | Q8: 1 | R8: 58.758562 | U8: 金华市 | V8: 3 | W8: 62.5
A9: 南昌市 | B9: 2 | C9: 98.902914 | F9: 阜阳市 | G9: 3 | H9: 71.25 | K9: 深圳市 | L9: 1 | M9: 91.25 | P9: 丽水市 | Q9: 4 | R9: 58.637336 | U9: 宜春市 | V9: 3 | W9: 62.5
A10: 鹤壁市 | B10: 3 | C10: 98.902914 | F10: 成都市 | G10: 1 | H10: 68.75 | K10: 西安市 | L10: 1 | M10: 91.25 | P10: 临沧市 | Q10: 4 | R10: 58.232252 | U10: 安庆市 | V10: 3 | W10: 62.5
A11: 七台河市 | B11: 4 | C11: 98.902914 | F11: 银川市 | G11: 2 | H11: 68.75 | K11: 临沂市 | L11: 2 | M11: 91.25 | P11: 广安市 | Q11: 4 | R11: 58.111599 | U11: 赤峰市 | V11: 2 | W11: 62.5
A12: 金昌市 | B12: 4 | C12: 98.902914 | F12: 昆明市 | G12: 1 | H12: 66.25 | K12: 荆州市 | L12: 3 | M12: 91.25 | P12: 曲靖市 | Q12: 3 | R12: 57.998166 | U12: 内江市 | V12: 3 | W12: 62.5
A13: 天津市 | B13: 1 | C13: 97.517554 | F13: 湖州市 | G13: 3 | H13: 66.25 | K13: 镇江市 | L13: 3 | M13: 91.25 | P13: 毕节市 | Q13: 3 | R13: 57.788433 | U13: 铜陵市 | V13: 3 | W13: 62.5
A14: 济宁市 | B14: 2 | C14: 96.265503 | F14: 扬州市 | G14: 2 | H14: 65 | K14: 威海市 | L14: 3 | M14: 91.25 | P14: 唐山市 | Q14: 2 | R14: 57.72341 | U14: 鹰潭市 | V14: 4 | W14: 62.5
A15: 阜阳市 | B15: 3 | C15: 96.265503 | F15: 安康市 | G15: 4 | H15: 65 | K15: 安康市 | L15: 4 | M15: 91.25 | P15: 濮阳市 | Q15: 3 | R15: 57.249584 | U15: 重庆市 | V15: 1 | W15: 50
A16: 惠州市 | B16: 2 | C16: 96.265503 | F16: 随州市 | G16: 4 | H16: 65 | K16: 东营市 | L16: 3 | M16: 91.25 | P16: 达州市 | Q16: 3 | R16: 57.230978 | U16: 上海市 | V16: 1 | W16: 50
A17: 聊城市 | B17: 2 | C17: 96.265503 | F17: 金华市 | G17: 3 | H17: 63.75 | K17: 马鞍山市 | L17: 3 | M17: 91.25 | P17: 德州市 | Q17: 3 | R17: 56.95896 | U17: 广州市 | V17: 1 | W17: 50
... A297: 衡阳市 | B297: 2 | C297: 13.187055 | F297: 贺州市 | G297: 4 | H297: 5 | K297: 林芝市 | L297: 4 | M297: 8.75 | P297: 日喀则市 | Q297: 4 | R297: 12.979398 | U297: 林芝市 | V297: 4 | W297: 0

Sheet Sheet3
A1: 城市 | B1: 环节 | J1: 维度总分 | K1: 维度排名 | O1: 城市 | P1: 城市分类 | Q1: 维度总分 | R1: 梯队 | AC1: 城市 | AD1: 城市分类 | AE1: 环节 | AJ1: 维度总分 | AK1: 维 度 排 名
B2: 城市分类 | C2: 规划（P） | E2: 实施 (D) | F2: 检查 (C) | G2: 结果(O) | I2: 反馈 （F） | O2: 北京市 | P2: 1 | Q2: 77.236589 | R2: 1 | S2: =(77.24-26.38)/4 -> 12.715 | T2: =S2+26.38 -> 39.095 | U2: 第四梯队 | AE2: 规划（P） | AF2: 实施（D） | AG2: 检查（C） | AH2: 结果（O） | AI2: 反馈（F）
C3: 初始得分 | D3: 修正后得分 | G3: 初始得分 | H3: 修正后得分 | O3: 杭州市 | P3: 1 | Q3: 70.030853 | R3: 1 | T3: =T2+S2 -> 51.81 | U3: 第三梯队
A4: 北京市 | B4: 1 | C4: 87.5 | D4: 84.290819 | E4: 95 | F4: 91.25 | G4: 60.99566 | H4: 58.758562 | I4: 87.5 | J4: 77.236589 | K4: 1 | O4: 上海市 | P4: 1 | Q4: 68.777127 | R4: 1 | T4: =T3+S2 -> 64.525 | U4: 第二梯队 | AC4: 北京市 | AD4: 1 | AE4: 84.290819 | AF4: 95 | AG4: 91.25 | AH4: 58.758562 | AI4: 87.5 | AJ4: 77.236589 | AK4: 1
A5: 杭州市 | B5: 1 | C5: 82.5 | D5: 80.796403 | E5: 88.75 | F5: 83.75 | G5: 51.683682 | H5: 50.616432 | I5: 75 | J5: 70.030853 | K5: 2 | O5: 金华市 | P5: 3 | Q5: 68.663131 | R5: 1 | T5: =T4+S2 -> 77.24 | U5: 第一梯队 | AC5: 杭州市 | AD5: 1 | AE5: 80.796403 | AF5: 88.75 | AG5: 83.75 | AH5: 50.616432 | AI5: 75 | AJ5: 70.030853 | AK5: 2
A6: 上海市 | B6: 1 | C6: 88.75 | D6: 85.494974 | E6: 87.5 | F6: 82.5 | G6: 54.312307 | H6: 52.32033 | I6: 50 | J6: 68.777127 | K6: 3 | O6: 宁波市 | P6: 2 | Q6: 68.116781 | R6: 1 | AC6: 上海市 | AD6: 1 | AE6: 85.494974 | AF6: 87.5 | AG6: 82.5 | AH6: 52.32033 | AI6: 50 | AJ6: 68.777127 | AK6: 3
A7: 金华市 | B7: 3 | C7: 93.75 | D7: 98.902914 | E7: 63.75 | F7: 83.75 | G7: 50.967473 | H7: 53.76887 | I7: 62.5 | J7: 68.663131 | K7: 4 | O7: 湖州市 | P7: 3 | Q7: 67.230492 | R7: 1 | AC7: 金华市 | AD7: 3 | AE7: 98.902914 | AF7: 63.75 | AG7: 83.75 | AH7: 53.76887 | AI7: 62.5 | AJ7: 68.663131 | AK7: 4
A8: 宁波市 | B8: 2 | C8: 100 | D8: 102.40521 | E8: 65 | F8: 82.5 | G8: 49.157014 | H8: 50.339346 | I8: 62.5 | J8: 68.116781 | K8: 5 | O8: 襄阳市 | P8: 2 | Q8: 66.205802 | R8: 1 | U8: 第一梯队 | V8: 第二梯队 | W8: 第三梯队 | X8: 第四梯队 | AC8: 宁波市 | AD8: 2 | AE8: 102.40521 | AF8: 65 | AG8: 82.5 | AH8: 50.339346 | AI8: 62.5 | AJ8: 68.116781 | AK8: 5
A9: 湖州市 | B9: 3 | C9: 85 | D9: 89.671975 | E9: 66.25 | F9: 83.75 | G9: 47.800421 | H9: 50.427743 | I9: 75 | J9: 67.230492 | K9: 6 | O9: 成都市 | P9: 1 | Q9: 65.948323 | R9: 1 | U9: (64.38-77.8,n=9) | V9: (50.96-64.38,n=95) | W9: (37.54-50.96, n=147) | X9: (24.12-37.54, n=43) | AC9: 湖州市 | AD9: 3 | AE9: 89.671975 | AF9: 66.25 | AG9: 83.75 | AH9: 50.427743 | AI9: 75 | AJ9: 67.230492 | AK9: 6
A10: 襄阳市 | B10: 2 | C10: 91.25 | D10: 96.265503 | E10: 75 | F10: 75 | G10: 52.022373 | H10: 54.881752 | I10: 25 | J10: 66.205802 | K10: 7 | O10: 重庆市 | P10: 1 | Q10: 65.490527 | R10: 1 | T10: 超大以及特大城市 | U10: 5 | V10: 11 | W10: 5 | X10: 0 | Y10: =SUM(U10:X10) -> 21 | AC10: 襄阳市 | AD10: 2 | AE10: 96.265503 | AF10: 75 | AG10: 75 | AH10: 54.881752 | AI10: 25 | AJ10: 66.205802 | AK10: 7
A11: 成都市 | B11: 1 | C11: 86.25 | D11: 85.313122 | E11: 81.25 | F11: 82.5 | G11: 39.518511 | H11: 39.089247 | I11: 87.5 | J11: 65.948323 | K11: 8 | T11: 大城市 | U11: 2 | V11: 38 | W11: 36 | X11: 4 | Y11: =SUM(U11:X11) -> 80 | AC11: 成都市 | AD11: 1 | AE11: 85.313122 | AF11: 81.25 | AG11: 82.5 | AH11: 39.089247 | AI11: 87.5 | AJ11: 65.948323 | AK11: 8
A12: 重庆市 | B12: 1 | C12: 80 | D12: 82.798646 | E12: 66.25 | F12: 75 | G12: 52.973807 | H12: 54.826994 | I12: 62.5 | J12: 65.490527 | K12: 9 | O12: 深圳市 | P12: 1 | Q12: 62.961829 | R12: 2 | T12: 中等城市 | U12: 2 | V12: 35 | W12: 65 | X12: 8 | Y12: =SUM(U12:X12) -> 110 | AC12: 重庆市 | AD12: 1 | AE12: 82.798646 | AF12: 66.25 | AG12: 75 | AH12: 54.826994 | AI12: 62.5 | AJ12: 65.490527 | AK12: 9
A13: 吉林市 | B13: 2 | C13: 85 | D13: 89.671975 | E13: 75 | F13: 91.25 | G13: 45.820289 | H13: 48.338774 | I13: 25 | J13: 63.894905 | K13: 10 | O13: 天津市 | P13: 1 | Q13: 62.282163 | R13: 2 | T13: 小城市 | U13: 0 | V13: 14 | W13: 52 | X13: 18 | Y13: =SUM(U13:X13) -> 84 | AC13: 吉林市 | AD13: 2 | AE13: 89.671975 | AF13: 75 | AG13: 91.25 | AH13: 48.338774 | AI13: 25 | AJ13: 63.894905 | AK13: 10
A14: 温州市 | B14: 2 | C14: 93.75 | D14: 98.902914 | E14: 58.75 | F14: 83.75 | G14: 47.612802 | H14: 50.229812 | I14: 37.5 | J14: 63.747507 | K14: 11 | O14: 武汉市 | P14: 1 | Q14: 61.705306 | R14: 2 | Y14: =SUM(Y10:Y13) -> 295 | AC14: 温州市 | AD14: 2 | AE14: 98.902914 | AF14: 58.75 | AG14: 83.75 | AH14: 50.229812 | AI14: 37.5 | AJ14: 63.747507 | AK14: 11
A15: 深圳市 | B15: 1 | C15: 91.25 | D15: 87.903283 | E15: 83.75 | F15: 91.25 | G15: 34.402178 | H15: 33.140432 | I15: 62.5 | J15: 62.961829 | K15: 12 | O15: 青岛市 | P15: 1 | Q15: 61.416107 | R15: 2 | AC15: 深圳市 | AD15: 1 | AE15: 87.903283 | AF15: 83.75 | AG15: 91.25 | AH15: 33.140432 | AI15: 62.5 | AJ15: 62.961829 | AK15: 12
A16: 广安市 | B16: 4 | C16: 78.75 | D16: 83.078448 | E16: 57.5 | F16: 75 | G16: 55.083943 | H16: 58.111599 | I16: 37.5 | J16: 62.610329 | K16: 13 | O16: 昆明市 | P16: 1 | Q16: 57.060544 | R16: 2 | AC16: 广安市 | AD16: 4 | AE16: 83.078448 | AF16: 57.5 | AG16: 75 | AH16: 58.111599 | AI16: 37.5 | AJ16: 62.610329 | AK16: 13
A17: 阜阳市 | B17: 3 | C17: 91.25 | D17: 96.265503 | E17: 71.25 | F17: 82.5 | G17: 46.023364 | H17: 48.553011 | I17: 12.5 | J17: 62.424305 | K17: 14 | O17: 广州市 | P17: 1 | Q17: 56.117144 | R17: 2 | AC17: 阜阳市 | AD17: 3 | AE17: 96.265503 | AF17: 71.25 | AG17: 82.5 | AH17: 48.553011 | AI17: 12.5 | AJ17: 62.424305 | AK17: 14
A18: 潍坊市 | B18: 2 | C18: 91.25 | D18: 93.872896 | E18: 58.75 | F18: 57.5 | G18: 51.194255 | H18: 52.665786 | I18: 50 | J18: 62.340894 | K18: 15 | O18: 南京市 | P18: 1 | Q18: 56.08515 | R18: 2 | T18: Means | AC18: 潍坊市 | AD18: 2 | AE18: 93.872896 | AF18: 58.75 | AG18: 57.5 | AH18: 52.665786 | AI18: 50 | AJ18: 62.340894 | AK18: 15
A19: 天津市 | B19: 1 | C19: 100 | D19: 97.517554 | E19: 68.75 | F19: 83.75 | G19: 40.130344 | H19: 39.13413 | I19: 50 | J19: 62.282163 | K19: 16 | O19: 西安市 | P19: 1 | Q19: 55.951757 | R19: 2 | T19: C4 | U19: N | V19: Mean | W19: StDev | X19: 95% CI | AC19: 天津市 | AD19: 1 | AE19: 97.517554 | AF19: 68.75 | AG19: 83.75 | AH19: 39.13413 | AI19: 50 | AJ19: 62.282163 | AK19: 16
A20: 十堰市 | B20: 2 | C20: 91.25 | D20: 96.265503 | E20: 75 | F20: 75 | G20: 42.471612 | H20: 44.80604 | I20: 25 | J20: 62.175517 | K20: 17 | O20: 郑州市 | P20: 1 | Q20: 55.926192 | R20: 2 | T20: 第一梯队 | U20: 9 | V20: 68.63 | W20: 3.56 | X20: (66.43, 70.84) | AC20: 十堰市 | AD20: 2 | AE20: 96.265503 | AF20: 75 | AG20: 75 | AH20: 44.80604 | AI20: 25 | AJ20: 62.175517 | AK20: 17
A21: 石家庄市 | B21: 2 | C21: 95 | D21: 95.219699 | E21: 63.75 | F21: 66.25 | G21: 46.121026 | H21: 46.227686 | I21: 50 | J21: 61.910014 | K21: 18 | O21: 长沙市 | P21: 1 | Q21: 55.111343 | R21: 2 | T21: 2 | U21: 98 | V21: 57.123 | W21: 3.212 | X21: (56.456, 57.791) | AC21: 石家庄市 | AD21: 2 | AE21: 95.219699 | AF21: 63.75 | AG21: 66.25 | AH21: 46.227686 | AI21: 50 | AJ21: 61.910014 | AK21: 18 | AN21: Means
A22: 南阳市 | B22: 3 | C22: 75 | D22: 79.122331 | E22: 46.25 | F22: 75 | G22: 60.398178 | H22: 63.717929 | I22: 37.5 | J22: 61.811638 | K22: 19 | O22: 东莞市 | P22: 1 | Q22: 54.477089 | R22: 2 | T22: 3 | U22: 158 | V22: 45.528 | W22: 3.425 | X22: (45.003, 46.054) | AC22: 南阳市 | AD22: 3 | AE22: 79.122331 | AF22: 46.25 | AG22: 75 | AH22: 63.717929 | AI22: 37.5 | AJ22: 61.811638 | AK22: 19 | AN22: C1 | AO22: N | AP22: Mean | AQ22: StDev | AR22: 95% CI
A23: 武威市 | B23: 4 | C23: 85 | D23: 89.671975 | E23: 58.75 | F23: 57.5 | G23: 56.447852 | H23: 59.550475 | I23: 25 | J23: 61.754585 | K23: 20 | O23: 吉林市 | P23: 2 | Q23: 63.894905 | R23: 2 | T23: 4 | U23: 31 | V23: 34.906 | W23: 3.414 | X23: (33.719, 36.093) | AC23: 武威市 | AD23: 4 | AE23: 89.671975 | AF23: 58.75 | AG23: 57.5 | AH23: 59.550475 | AI23: 25 | AJ23: 61.754585 | AK23: 20 | AN23: 超大以及特大城市 | AO23: 21 | AP23: 58.34 | AQ23: 8.59 | AR23: (54.99, 61.69)
A24: 武汉市 | B24: 1 | C24: 82.5 | D24: 79.474201 | E24: 62.5 | F24: 75 | G24: 44.27501 | H24: 42.651165 | I24: 87.5 | J24: 61.705306 | K24: 21 | O24: 温州市 | P24: 2 | Q24: 63.747507 | R24: 2 | T24: Pooled StDev = 3.35848 | AC24: 武汉市 | AD24: 1 | AE24: 79.474201 | AF24: 62.5 | AG24: 75 | AH24: 42.651165 | AI24: 87.5 | AJ24: 61.705306 | AK24: 21 | AN24: 大城市 | AO24: 80 | AP24: 51.003 | AQ24: 8.145 | AR24: (49.286, 52.720)
A25: 安庆市 | B25: 3 | C25: 75 | D25: 79.122331 | E25: 53.75 | F25: 75 | G25: 50.566325 | H25: 53.345674 | I25: 62.5 | J25: 61.662736 | K25: 22 | O25: 潍坊市 | P25: 2 | Q25: 62.340894 | R25: 2 | AC25: 安庆市 | AD25: 3 | AE25: 79.122331 | AF25: 53.75 | AG25: 75 | AH25: 53.345674 | AI25: 62.5 | AJ25: 61.662736 | AK25: 22 | AN25: 中等城市 | AO25: 111 | AP25: 48.711 | AQ25: 7.572 | AR25: (47.254, 50.169)
A26: 中山市 | B26: 2 | C26: 78.75 | D26: 83.078448 | E26: 38.75 | F26: 82.5 | G26: 56.812137 | H26: 59.934783 | I26: 50 | J26: 61.589603 | K26: 23 | O26: 十堰市 | P26: 2 | Q26: 62.175517 | R26: 2 | AC26: 中山市 | AD26: 2 | AE26: 83.078448 | AF26: 38.75 | AG26: 82.5 | AH26: 59.934783 | AI26: 50 | AJ26: 61.589603 | AK26: 23 | AN26: 小城市 | AO26: 84 | AP26: 44.988 | AQ26: 7.566 | AR26: (43.312, 46.663)
A27: 德州市 | B27: 3 | C27: 85 | D27: 89.671975 | E27: 53.75 | F27: 75 | G27: 53.991357 | H27: 56.95896 | I27: 25 | J27: 61.467979 | K27: 24 | O27: 石家庄市 | P27: 2 | Q27: 61.910014 | R27: 2 | T27: Grouping Information Using the Tukey Method and 95% Confidence | AC27: 德州市 | AD27: 3 | AE27: 89.671975 | AF27: 53.75 | AG27: 75 | AH27: 56.95896 | AI27: 25 | AJ27: 61.467979 | AK27: 24 | AN27: Pooled StDev = 7.80239
A28: 青岛市 | B28: 1 | C28: 76.25 | D28: 75.667531 | E28: 66.25 | F28: 73.75 | G28: 48.892488 | H28: 48.519001 | I28: 62.5 | J28: 61.416107 | K28: 25 | O28: 中山市 | P28: 2 | Q28: 61.589603 | R28: 2 | T28: C4 | U28: N | V28: Mean | W28: Grouping | AC28: 青岛市 | AD28: 1 | AE28: 75.667531 | AF28: 66.25 | AG28: 73.75 | AH28: 48.519001 | AI28: 62.5 | AJ28: 61.416107 | AK28: 25
A29: 鹰潭市 | B29: 4 | C29: 81.25 | D29: 85.715859 | E29: 53.75 | F29: 75 | G29: 46.496585 | H29: 49.052243 | I29: 62.5 | J29: 61.264069 | K29: 26 | O29: 福州市 | P29: 2 | Q29: 61.180026 | R29: 2 | T29: 1 | U29: 9 | V29: 68.63 | W29: A | AC29: 鹰潭市 | AD29: 4 | AE29: 85.715859 | AF29: 53.75 | AG29: 75 | AH29: 49.052243 | AI29: 62.5 | AJ29: 61.264069 | AK29: 26
