Workbook

Sheet 森林得分
A1: 城市 | B1: P | C1: I | D1: C | E1: O | F1: F | G1: Fo-α | H1: Wp | I1: WI | J1: WC | K1: WO | L1: WF | M1: Fo维度得分 | N1: P修正 | O1: O修正
A3: 重庆 | B3: 45 | C3: 71.25 | D3: 50 | E3: 84.191477 | F3: 43.333333 | G3: 0.97133735 | H3: 0.2 | I3: 0.2 | J3: 0.15 | K3: 0.3 | L3: 0.15 | M3: =((G3*$H$3*B3)+($I$3*C3)+($J$3*D3)+(G3*$K$3*E3)+($L$3*F3)) -> 61.525534 | N3: =B3*G3 -> 43.710181 | O3: =E3*G3 -> 81.778326
A4: 成都 | B4: 32.5 | C4: 77.5 | D4: 75 | E4: 71.758593 | F4: 60 | G4: 0.97656579 | M4: =((G4*$H$3*B4)+($I$3*C4)+($J$3*D4)+(G4*$K$3*E4)+($L$3*F4)) -> 63.120774 | N4: =B4*G4 -> 31.738388 | O4: =E4*G4 -> 70.076987
A5: 上海 | B5: 32.5 | C5: 60 | D5: 66.666667 | E5: 36.959129 | F5: 60 | G5: 0.98622317 | M5: =((G5*$H$3*B5)+($I$3*C5)+($J$3*D5)+(G5*$K$3*E5)+($L$3*F5)) -> 48.345435 | N5: =B5*G5 -> 32.052253 | O5: =E5*G5 -> 36.449949
A6: 北京 | B6: 42.5 | C6: 100 | D6: 91.666667 | E6: 53.142945 | F6: 66.666667 | G6: 1.0861884 | M6: =((G6*$H$3*B6)+($I$3*C6)+($J$3*D6)+(G6*$K$3*E6)+($L$3*F6)) -> 70.299577 | N6: =B6*G6 -> 46.163008 | O6: =E6*G6 -> 57.723252
A7: 周口市 | B7: 20 | C7: 65 | D7: 83.333333 | E7: 38.657663 | F7: 43.333333 | G7: 1.0685297 | M7: =((G7*$H$3*B7)+($I$3*C7)+($J$3*D7)+(G7*$K$3*E7)+($L$3*F7)) -> 48.666178 | N7: =B7*G7 -> 21.370595 | O7: =E7*G7 -> 41.306862
A8: 南阳市 | B8: 20 | C8: 65 | D8: 41.666667 | E8: 60.612736 | F8: 60 | G8: 1.0664658 | M8: =((G8*$H$3*B8)+($I$3*C8)+($J$3*D8)+(G8*$K$3*E8)+($L$3*F8)) -> 51.908287 | N8: =B8*G8 -> 21.329316 | O8: =E8*G8 -> 64.641411
A9: 保定市 | B9: 10 | C9: 53.75 | D9: 41.666667 | E9: 68.173293 | F9: 26.666667 | G9: 1.0661896 | M9: =((G9*$H$3*B9)+($I$3*C9)+($J$3*D9)+(G9*$K$3*E9)+($L$3*F9)) -> 44.938077 | N9: =B9*G9 -> 10.661896 | O9: =E9*G9 -> 72.685658
A10: 临沂市 | B10: 0 | C10: 71.25 | D10: 75 | E10: 52.632332 | F10: 60 | G10: 1.023796 | M10: =((G10*$H$3*B10)+($I$3*C10)+($J$3*D10)+(G10*$K$3*E10)+($L$3*F10)) -> 50.665431 | N10: =B10*G10 -> 0 | O10: =E10*G10 -> 53.884769
A11: 天津 | B11: 10 | C11: 72.5 | D11: 66.666667 | E11: 37.018319 | F11: 66.666667 | G11: 1.0752526 | M11: =((G11*$H$3*B11)+($I$3*C11)+($J$3*D11)+(G11*$K$3*E11)+($L$3*F11)) -> 48.591718 | N11: =B11*G11 -> 10.752526 | O11: =E11*G11 -> 39.804043
A12: 阜阳市 | B12: 65 | C12: 76.25 | D12: 75 | E12: 57.956359 | F12: 43.333333 | G12: 1.02434 | M12: =((G12*$H$3*B12)+($I$3*C12)+($J$3*D12)+(G12*$K$3*E12)+($L$3*F12)) -> 64.126524 | N12: =B12*G12 -> 66.582097 | O12: =E12*G12 -> 59.367014
A13: 邯郸市 | B13: 10 | C13: 77.5 | D13: 66.666667 | E13: 71.57621 | F13: 66.666667 | G13: 1.0787373 | M13: =((G13*$H$3*B13)+($I$3*C13)+($J$3*D13)+(G13*$K$3*E13)+($L$3*F13)) -> 60.821053 | N13: =B13*G13 -> 10.787373 | O13: =E13*G13 -> 77.211928
A14: 石家庄 | B14: 40 | C14: 53.75 | D14: 66.666667 | E14: 71.697614 | F14: 43.333333 | G14: 1.0571651 | M14: =((G14*$H$3*B14)+($I$3*C14)+($J$3*D14)+(G14*$K$3*E14)+($L$3*F14)) -> 58.446187 | N14: =B14*G14 -> 42.286606 | O14: =E14*G14 -> 75.796218
A15: 徐州市 | B15: 10 | C15: 33.75 | D15: 33.333333 | E15: 59.218544 | F15: 26.666667 | G15: 1.0323832 | M15: =((G15*$H$3*B15)+($I$3*C15)+($J$3*D15)+(G15*$K$3*E15)+($L$3*F15)) -> 36.155636 | N15: =B15*G15 -> 10.323832 | O15: =E15*G15 -> 61.136231
... A294: 嘉峪关市 | B294: 10 | C294: 83.75 | D294: 91.666667 | E294: 42.455547 | F294: 66.666667 | G294: 1.0861884 | M294: =((G294*$H$3*B294)+($I$3*C294)+($J$3*D294)+(G294*$K$3*E294)+($L$3*F294)) -> 56.506794 | N294: =B294*G294 -> 10.861884 | O294: =E294*G294 -> 46.114724
A295: 三沙市 | B295: 0 | C295: 5 | D295: 0 | E295: / | F295: 13.333333 | G295: / | M295: / | N295: / | O295: /
A296: 那曲市 | B296: 0 | C296: 32.5 | D296: 25 | E296: 36.687237 | F296: 43.333333 | G296: 1.0861884 | M296: =((G296*$H$3*B296)+($I$3*C296)+($J$3*D296)+(G296*$K$3*E296)+($L$3*F296)) -> 28.704776 | N296: =B296*G296 -> 0 | O296: =E296*G296 -> 39.849252
A297: 乌鲁木齐 | B297: 10 | C297: 71.25 | D297: 91.666667 | E297: 37.794197 | F297: 60 | G297: 1.0861884 | M297: =((G297*$H$3*B297)+($I$3*C297)+($J$3*D297)+(G297*$K$3*E297)+($L$3*F297)) -> 51.487863 | N297: =B297*G297 -> 10.861884 | O297: =E297*G297 -> 41.05162
A298: 吐鲁番市 | B298: 0 | C298: 82.5 | D298: 91.666667 | E298: 31.913122 | F298: 66.666667 | G298: 1.0861884 | M298: =((G298*$H$3*B298)+($I$3*C298)+($J$3*D298)+(G298*$K$3*E298)+($L$3*F298)) -> 50.649099 | N298: =B298*G298 -> 0 | O298: =E298*G298 -> 34.663664
A299: 哈密市 | B299: 0 | C299: 70 | D299: 66.666667 | E299: 32.271857 | F299: 43.333333 | G299: 1.0861884 | M299: =((G299*$H$3*B299)+($I$3*C299)+($J$3*D299)+(G299*$K$3*E299)+($L$3*F299)) -> 41.015995 | N299: =B299*G299 -> 0 | O299: =E299*G299 -> 35.053317

Sheet 1.0 排序
A1: 城市 | B1: P | C1: I | D1: C | E1: O | F1: F | G1: Fo-α | H1: Wp | I1: WI | J1: WC | K1: WO | L1: WF | M1: Fo维度得分 | N1: 300城市排序 | O1: 36城市排序 | P1: 1.0排序
A2: 昆明 | B2: 65 | C2: 82.5 | D2: 91.666667 | E2: 77.586833 | F2: 66.666667 | G2: 0.93985671 | M2: 73.719673 | N2: 3 | O2: =RANK(M2,$M$2:$M$37,0) -> 1 | P2: 4 | Q2: =O2-P2 -> -3
A3: 北京 | B3: 42.5 | C3: 100 | D3: 91.666667 | E3: 53.142945 | F3: 66.666667 | G3: 1.0861884 | M3: 68.155236 | N3: 19 | O3: =RANK(M3,$M$2:$M$37,0) -> 2 | P3: 1 | Q3: =O3-P3 -> 1
A4: 呼和浩特 | B4: 52.5 | C4: 83.75 | D4: 91.666667 | E4: 55.534089 | F4: 66.666667 | G4: 1.0861884 | M4: 68.116505 | N4: 20 | O4: =RANK(M4,$M$2:$M$37,0) -> 3 | P4: 6 | Q4: =O4-P4 -> -3
A5: 南宁 | B5: 77.5 | C5: 58.75 | D5: 75 | E5: 77.437437 | F5: 43.333333 | G5: 0.92035842 | M5: 66.356968 | N5: 27 | O5: =RANK(M5,$M$2:$M$37,0) -> 4 | P5: 2 | Q5: =O5-P5 -> 2
A6: 重庆 | B6: 45 | C6: 71.25 | D6: 50 | E6: 84.191477 | F6: 43.333333 | G6: 0.97133735 | H6: 0.2 | I6: 0.2 | J6: 0.1 | K6: 0.4 | L6: 0.1 | M6: 65.0367 | N6: 32 | O6: =RANK(M6,$M$2:$M$37,0) -> 5 | P6: 3 | Q6: =O6-P6 -> 2
A7: 广州 | B7: 55 | C7: 65 | D7: 91.666667 | E7: 75.142237 | F7: 50 | G7: 0.92035842 | M7: 64.953725 | N7: 34 | O7: =RANK(M7,$M$2:$M$37,0) -> 6 | P7: 16 | Q7: =O7-P7 -> -10
A8: 成都 | B8: 32.5 | C8: 77.5 | D8: 75 | E8: 71.758593 | F8: 60 | G8: 0.97656579 | M8: 63.378472 | N8: 41 | O8: =RANK(M8,$M$2:$M$37,0) -> 7 | P8: 21 | Q8: =O8-P8 -> -14
A9: 海口 | B9: 77.5 | C9: 65 | D9: 50 | E9: 67.477199 | F9: 43.333333 | G9: 0.92035842 | M9: 61.440172 | N9: 53 | O9: =RANK(M9,$M$2:$M$37,0) -> 8 | P9: 8 | Q9: =O9-P9 -> 0
A10: 合肥 | B10: 55 | C10: 82.5 | D10: 58.333333 | E10: 51.729793 | F10: 66.666667 | G10: 1.0083593 | M10: 60.95684 | N10: 58 | O10: =RANK(M10,$M$2:$M$37,0) -> 9 | P10: 12 | Q10: =O10-P10 -> -3
A11: 福州 | B11: 75 | C11: 60 | D11: 58.333333 | E11: 72.267148 | F11: 26.666667 | G11: 0.92035842 | M11: 60.910047 | N11: 59 | O11: =RANK(M11,$M$2:$M$37,0) -> 10 | P11: 15 | Q11: =O11-P11 -> -5
A12: 武汉 | B12: 75 | C12: 71.25 | D12: 50 | E12: 60.000911 | F12: 30 | G12: 0.98340425 | M12: 60.603124 | N12: 60 | O12: =RANK(M12,$M$2:$M$37,0) -> 11 | P12: 28 | Q12: =O12-P12 -> -17
A13: 石家庄 | B13: 40 | C13: 53.75 | D13: 66.666667 | E13: 71.697614 | F13: 43.333333 | G13: 1.0571651 | M13: 60.525809 | N13: 61 | O13: =RANK(M13,$M$2:$M$37,0) -> 12 | P13: 20 | Q13: =O13-P13 -> -8
A14: 杭州 | B14: 52.5 | C14: 71.25 | D14: 58.333333 | E14: 67.221252 | F14: 43.333333 | G14: 0.9399434 | M14: 59.559741 | N14: 70 | O14: =RANK(M14,$M$2:$M$37,0) -> 13 | P14: 9 | Q14: =O14-P14 -> 4
A15: 西安 | B15: 77.5 | C15: 53.75 | D15: 58.333333 | E15: 54.221434 | F15: 43.333333 | G15: 0.99647244 | M15: 57.974055 | N15: 82 | O15: =RANK(M15,$M$2:$M$37,0) -> 14 | P15: 7 | Q15: =O15-P15 -> 7
A16: 太原 | B16: 0 | C16: 82.5 | D16: 75 | E16: 64.768364 | F16: 43.333333 | G16: 1.0594613 | M16: 57.447831 | N16: 86 | O16: =RANK(M16,$M$2:$M$37,0) -> 15 | P16: 34 | Q16: =O16-P16 -> -19
A17: 大连市 | B17: 67.5 | C17: 58.75 | D17: 58.333333 | E17: 58.155197 | F17: 26.666667 | G17: 1.0103917 | M17: 57.3941 | N17: 87 | O17: =RANK(M17,$M$2:$M$37,0) -> 16 | P17: 10 | Q17: =O17-P17 -> 6
A18: 深圳市 | B18: 20 | C18: 77.5 | D18: 75 | E18: 71.320439 | F18: 33.333333 | G18: 0.92035842 | M18: 56.270914 | N18: 101 | O18: =RANK(M18,$M$2:$M$37,0) -> 17 | P18: 36 | Q18: =O18-P18 -> -19
... A37: 长春 | B37: 10 | C37: 38.75 | D37: 58.333333 | E37: 51.280733 | F37: 43.333333 | G37: 1.028867 | M37: 41.078822 | N37: 251 | O37: =RANK(M37,$M$2:$M$37,0) -> 36 | P37: 27 | Q37: =O37-P37 -> 9

Sheet 森林排序
A1: 城市 | B1: P | C1: I | D1: C | E1: O | F1: F | G1: Fo-α | H1: Wp | I1: WI | J1: WC | K1: WO | L1: WF | M1: Fo维度得分 | N1: 排序
A2: 广元市 | B2: 55 | C2: 88.75 | D2: 91.666667 | E2: 78.059629 | F2: 66.666667 | G2: 0.98137999 | M2: 75.277027 | N2: 1
A3: 池州市 | B3: 75 | C3: 88.75 | D3: 91.666667 | E3: 67.458543 | F3: 66.666667 | G3: 0.95043016 | M3: 74.990843 | N3: 2
A4: 昆明 | B4: 65 | C4: 82.5 | D4: 91.666667 | E4: 77.586833 | F4: 66.666667 | G4: 0.93985671 | M4: 74.344289 | N4: 3
A5: 黄冈市 | B5: 75 | C5: 87.5 | D5: 83.333333 | E5: 68.646904 | F5: 60 | G5: 0.98363848 | M5: 74.011698 | N5: 4
A6: 伊春市 | B6: 75 | C6: 60 | D6: 83.333333 | E6: 84.711302 | F6: 43.333333 | G6: 1.0481479 | M6: 73.35921 | N6: 5
A7: 九江市 | B7: 65 | C7: 88.75 | D7: 91.666667 | E7: 68.2938 | F7: 66.666667 | G7: 0.94411173 | M7: 73.116546 | N7: 6
A8: 玉溪市 | B8: 65 | C8: 76.25 | D8: 91.666667 | E8: 75.111472 | F8: 66.666667 | G8: 0.95557277 | M8: 72.954789 | N8: 7
A9: 毕节市 | B9: 65 | C9: 77.5 | D9: 83.333333 | E9: 78.239174 | F9: 60 | G9: 0.96096694 | M9: 72.048148 | N9: 8
A10: 贺州市 | B10: 77.5 | C10: 70 | D10: 91.666667 | E10: 75.224706 | F10: 60 | G10: 0.92035842 | M10: 71.785663 | N10: 9
A11: 荆门市 | B11: 75 | C11: 88.75 | D11: 91.666667 | E11: 55.775268 | F11: 50 | G11: 1.0097819 | M11: 71.042986 | N11: 10
A12: 延安市 | B12: 65 | C12: 76.25 | D12: 83.333333 | E12: 60.916305 | F12: 60 | G12: 1.0819188 | M12: 70.586893 | N12: 11
A13: 巴中市 | B13: 65 | C13: 88.75 | D13: 66.666667 | E13: 73.427183 | F13: 60 | G13: 0.95944404 | M13: 70.357554 | N13: 12
... A54: 七台河市 | B54: 30 | C54: 66.25 | D54: 75 | E54: 68.017657 | F54: 60 | G54: 1.0670995 | M54: 61.67708 | N54: 53
A55: 重庆 | B55: 45 | C55: 71.25 | D55: 50 | E55: 84.191477 | F55: 43.333333 | G55: 0.97133735 | H55: 0.2 | I55: 0.2 | J55: 0.15 | K55: 0.3 | L55: 0.15 | M55: 61.525534 | N55: 54
A56: 玉林市 | B56: 75 | C56: 66.25 | D56: 83.333333 | E56: 54.594305 | F56: 43.333333 | G56: 0.92035842 | M56: 61.129275 | N56: 55
A57: 承德市 | B57: 10 | C57: 65 | D57: 83.333333 | E57: 71.671178 | F57: 66.666667 | G57: 1.0861884 | M57: 61.026898 | N57: 56
A58: 宜昌市 | B58: 20 | C58: 76.25 | D58: 91.666667 | E58: 63.913718 | F58: 60 | G58: 0.98830925 | M58: 60.903193 | N58: 57
A59: 邯郸市 | B59: 10 | C59: 77.5 | D59: 66.666667 | E59: 71.57621 | F59: 66.666667 | G59: 1.0787373 | M59: 60.821053 | N59: 58
A60: 丽江市 | B60: 10 | C60: 76.25 | D60: 66.666667 | E60: 81.435126 | F60: 66.666667 | G60: 0.94678786 | M60: 60.274112 | N60: 59
A61: 邢台市 | B61: 65 | C61: 65 | D61: 33.333333 | E61: 63.927076 | F61: 50 | G61: 1.0787019 | M61: 60.210603 | N61: 60
A62: 烟台市 | B62: 12.5 | C62: 77.5 | D62: 91.666667 | E62: 60.374359 | F62: 66.666667 | G62: 1.0163769 | M62: 60.199874 | N62: 61
A63: 海口 | B63: 77.5 | C63: 65 | D63: 50 | E63: 67.477199 | F63: 43.333333 | G63: 0.92035842 | M63: 59.896518 | N63: 62
A64: 赤峰市 | B64: 75 | C64: 46.25 | D64: 66.666667 | E64: 61.453985 | F64: 26.666667 | G64: 1.0861884 | M64: 59.568009 | N64: 63
A65: 眉山市 | B65: 42.5 | C65: 77.5 | D65: 83.333333 | E65: 53.97622 | F65: 50 | G65: 0.97240047 | M65: 59.511354 | N65: 64
A66: 梧州市 | B66: 65 | C66: 65 | D66: 66.666667 | E66: 56.091241 | F66: 60 | G66: 0.92035842 | M66: 59.451873 | N66: 65
A67: 广安市 | B67: 32.5 | C67: 82.5 | D67: 83.333333 | E67: 47.13998 | F67: 66.666667 | G67: 0.98703729 | M67: 59.374418 | N67: 66
... A297: 资阳市 | B297: 0 | C297: 0 | D297: 0 | E297: 54.015198 | F297: 0 | G297: 1.0151991 | M297: 16.450855 | N297: 296
A298: 三沙市 | B298: 0 | C298: 5 | D298: 0 | E298: / | F298: 13.333333 | G298: / | M298: / | N298: /

Sheet Top 25%
A1: 城市 | B1: P | C1: I | D1: C | E1: O | F1: F | G1: Fo-α | H1: Wp | I1: WI | J1: WC | K1: WO | L1: WF | M1: Fo维度得分 | N1: 排序 | O1: 行政组别
A2: 黄冈市 | B2: 87.5 | C2: 87.5 | D2: 83.333333 | E2: 68.646904 | F2: 60 | G2: 0.98363848 | M2: 76.056501 | N2: 1 | O2: =VLOOKUP(A2,[1]Sheet1!$A$1:$I$297,2,FALSE) -> 4
A3: 伊春市 | B3: 75 | C3: 60 | D3: 83.333333 | E3: 84.711302 | F3: 43.333333 | G3: 1.0481479 | M3: 75.904874 | N3: 2 | O3: =VLOOKUP(A3,[1]Sheet1!$A$1:$I$297,2,FALSE) -> 4
A4: 广元市 | B4: 55 | C4: 88.75 | D4: 91.666667 | E4: 78.059629 | F4: 66.666667 | G4: 0.98137999 | M4: 75.020976 | N4: 3 | O4: 1
A5: 1 | B5: 65 | C5: 82.5 | D5: 91.666667 | E5: 77.586833 | F5: 66.666667 | G5: 0.93985671 | M5: 73.719673 | N5: 4 | O5: =VLOOKUP(A5,[1]Sheet1!$A$1:$I$297,2,FALSE) -> #N/A
A6: 池州市 | B6: 75 | C6: 88.75 | D6: 91.666667 | E6: 67.458543 | F6: 66.666667 | G6: 0.95043016 | M6: 73.485639 | N6: 5 | O6: =VLOOKUP(A6,[1]Sheet1!$A$1:$I$297,2,FALSE) -> 4
A7: 毕节市 | B7: 65 | C7: 77.5 | D7: 83.333333 | E7: 78.239174 | F7: 60 | G7: 0.96096694 | M7: 72.400007 | N7: 6 | O7: =VLOOKUP(A7,[1]Sheet1!$A$1:$I$297,2,FALSE) -> 3
A8: 玉溪市 | B8: 65 | C8: 76.25 | D8: 91.666667 | E8: 75.111472 | F8: 66.666667 | G8: 0.95557277 | M8: 72.21557 | N8: 7 | O8: =VLOOKUP(A8,[1]Sheet1!$A$1:$I$297,2,FALSE) -> 3
A9: 九江市 | B9: 65 | C9: 88.75 | D9: 91.666667 | E9: 68.2938 | F9: 66.666667 | G9: 0.94411173 | M9: 71.647577 | N9: 8 | O9: =VLOOKUP(A9,[1]Sheet1!$A$1:$I$297,2,FALSE) -> 3
A10: 贺州市 | B10: 77.5 | C10: 70 | D10: 91.666667 | E10: 75.224706 | F10: 60 | G10: 0.92035842 | M10: 71.125699 | N10: 9 | O10: =VLOOKUP(A10,[1]Sheet1!$A$1:$I$297,2,FALSE) -> 4
A11: 巴中市 | B11: 65 | C11: 88.75 | D11: 66.666667 | E11: 73.427183 | F11: 60 | G11: 0.95944404 | M11: 71.069148 | N11: 10 | O11: =VLOOKUP(A11,[1]Sheet1!$A$1:$I$297,2,FALSE) -> 4
A12: 保山市 | B12: 65 | C12: 71.25 | D12: 75 | E12: 82.148222 | F12: 66.666667 | G12: 0.92250084 | M12: 70.721899 | N12: 11 | O12: =VLOOKUP(A12,[1]Sheet1!$A$1:$I$297,2,FALSE) -> 4
A13: 吉林市 | B13: 10 | C13: 88.75 | D13: 91.666667 | E13: 87.502182 | F13: 66.666667 | G13: 0.99789864 | M13: 70.506454 | N13: 12 | O13: =VLOOKUP(A13,[1]Sheet1!$A$1:$I$297,2,FALSE) -> 2
A14: 延安市 | B14: 65 | C14: 76.25 | D14: 83.333333 | E14: 60.916305 | F14: 60 | G14: 1.0819188 | M14: 70.010876 | N14: 13 | O14: =VLOOKUP(A14,[1]Sheet1!$A$1:$I$297,2,FALSE) -> 4
A15: 黄山市 | B15: 65 | C15: 82.5 | D15: 83.333333 | E15: 75.197538 | F15: 50 | G15: 0.93246305 | M15: 70.002923 | N15: 14 | O15: =VLOOKUP(A15,[1]Sheet1!$A$1:$I$297,2,FALSE) -> 4
A16: 荆门市 | B16: 75 | C16: 88.75 | D16: 91.666667 | E16: 55.775268 | F16: 50 | G16: 1.0097819 | M16: 69.591738 | N16: 15 | O16: =VLOOKUP(A16,[1]Sheet1!$A$1:$I$297,2,FALSE) -> 3
A17: 呼伦贝尔市 | B17: 20 | C17: 76.25 | D17: 83.333333 | E17: 83.012558 | F17: 50 | G17: 1.0861884 | M17: 68.994999 | N17: 16 | O17: =VLOOKUP(A17,[1]Sheet1!$A$1:$I$297,2,FALSE) -> 4
... A34: 新余市 | B34: 52.5 | C34: 81.25 | D34: 83.333333 | E34: 67.978464 | F34: 60 | G34: 0.92035842 | M34: 65.272917 | N34: 33 | O34: =VLOOKUP(A34,[1]Sheet1!$A$1:$I$297,2,FALSE) -> 3
A35: 重庆 | B35: 45 | C35: 71.25 | D35: 50 | E35: 84.191477 | F35: 43.333333 | G35: 0.97133735 | H35: 0.2 | I35: 0.2 | J35: 0.1 | K35: 0.4 | L35: 0.1 | M35: 65.0367 | N35: 34 | O35: =VLOOKUP(A35,[1]Sheet1!$A$1:$I$297,2,FALSE) -> #N/A
A36: 广州 | B36: 55 | C36: 65 | D36: 91.666667 | E36: 75.142237 | F36: 50 | G36: 0.92035842 | M36: 64.953725 | N36: 35 | O36: =VLOOKUP(A36,[1]Sheet1!$A$1:$I$297,2,FALSE) -> #N/A
A37: 渭南市 | B37: 65 | C37: 66.25 | D37: 83.333333 | E37: 57.83675 | F37: 50 | G37: 1.0584513 | M37: 64.830155 | N37: 36 | O37: =VLOOKUP(A37,[1]Sheet1!$A$1:$I$297,2,FALSE) -> 4
A38: 崇左市 | B38: 87.5 | C38: 56.25 | D38: 75 | E38: 62.489526 | F38: 66.666667 | G38: 0.9235476 | M38: 64.663571 | N38: 37 | O38: =VLOOKUP(A38,[1]Sheet1!$A$1:$I$297,2,FALSE) -> 4
A39: 马鞍山市 | B39: 75 | C39: 77.5 | D39: 91.666667 | E39: 46.511653 | F39: 66.666667 | G39: 0.99104691 | M39: 64.637129 | N39: 38 | O39: =VLOOKUP(A39,[1]Sheet1!$A$1:$I$297,2,FALSE) -> 3
A40: 上饶市 | B40: 75 | C40: 70 | D40: 75 | E40: 67.489974 | F40: 43.333333 | G40: 0.92035842 | M40: 64.484696 | N40: 39 | O40: =VLOOKUP(A40,[1]Sheet1!$A$1:$I$297,2,FALSE) -> 2
A41: 阜阳市 | B41: 65 | C41: 76.25 | D41: 75 | E41: 57.956359 | F41: 43.333333 | G41: 1.02434 | M41: 64.146559 | N41: 40 | O41: =VLOOKUP(A41,[1]Sheet1!$A$1:$I$297,2,FALSE) -> 3
A42: 汕尾市 | B42: 65 | C42: 77.5 | D42: 75 | E42: 71.470683 | F42: 26.666667 | G42: 0.92035842 | M42: 63.942784 | N42: 41 | O42: =VLOOKUP(A42,[1]Sheet1!$A$1:$I$297,2,FALSE) -> 4
A43: 成都 | B43: 32.5 | C43: 77.5 | D43: 75 | E43: 71.758593 | F43: 60 | G43: 0.97656579 | M43: 63.378472 | N43: 42 | O43: =VLOOKUP(A43,[1]Sheet1!$A$1:$I$297,2,FALSE) -> #N/A
A44: 抚州市 | B44: 77.5 | C44: 88.75 | D44: 75 | E44: 48.491378 | F44: 60 | G44: 0.92035842 | M44: 63.367335 | N44: 43 | O44: =VLOOKUP(A44,[1]Sheet1!$A$1:$I$297,2,FALSE) -> 3
A45: 邢台市 | B45: 65 | C45: 65 | D45: 33.333333 | E45: 63.927076 | F45: 50 | G45: 1.0787019 | M45: 62.939763 | N45: 44 | O45: =VLOOKUP(A45,[1]Sheet1!$A$1:$I$297,2,FALSE) -> 2
A46: 揭阳市 | B46: 35 | C46: 71.25 | D46: 91.666667 | E46: 71.703712 | F46: 66.666667 | G46: 0.92035842 | M46: 62.923088 | N46: 45 | O46: =VLOOKUP(A46,[1]Sheet1!$A$1:$I$297,2,FALSE) -> 3
A47: 淮南市 | B47: 75 | C47: 75 | D47: 66.666667 | E47: 46.267039 | F47: 66.666667 | G47: 1.0248351 | M47: 62.672293 | N47: 46 | O47: =VLOOKUP(A47,[1]Sheet1!$A$1:$I$297,2,FALSE) -> 2
... A70: 宜昌市 | B70: 20 | C70: 76.25 | D70: 91.666667 | E70: 63.913718 | F70: 60 | G70: 0.98830925 | M70: 59.636511 | N70: 69 | O70: =VLOOKUP(A70,[1]Sheet1!$A$1:$I$297,2,FALSE) -> 2
A71: 牡丹江市 | B71: 0 | C71: 50 | D71: 66.666667 | E71: 87.727467 | F71: 60 | G71: 1.0514953 | M71: 59.564673 | N71: 70 | O71: 1
A72: 杭州 | B72: 52.5 | C72: 71.25 | D72: 58.333333 | E72: 67.221252 | F72: 43.333333 | G72: 0.9399434 | M72: 59.559741 | N72: 71 | O72: 1
A73: 三明市 | B73: 55 | C73: 66.25 | D73: 25 | E73: 82.600121 | F73: 26.666667 | G73: 0.92035842 | M73: 58.949296 | N73: 72 | O73: =VLOOKUP(A73,[1]Sheet1!$A$1:$I$297,2,FALSE) -> 4
A74: 陇南市 | B74: 55 | C74: 47.5 | D74: 58.333333 | E74: 70.983312 | F74: 43.333333 | G74: 0.9966825 | M74: 58.929304 | N74: 73 | O74: =VLOOKUP(A74,[1]Sheet1!$A$1:$I$297,2,FALSE) -> 4
A75: 咸阳市 | B75: 25 | C75: 72.5 | D75: 58.333333 | E75: 67.201479 | F75: 43.333333 | G75: 1.0661508 | M75: 58.656184 | N75: 74 | O75: =VLOOKUP(A75,[1]Sheet1!$A$1:$I$297,2,FALSE) -> 2
A76: 茂名市 | B76: 52.5 | C76: 60 | D76: 75 | E76: 72.83624 | F76: 26.666667 | G76: 0.92035842 | M76: 58.644609 | N76: 75 | O76: =VLOOKUP(A76,[1]Sheet1!$A$1:$I$297,2,FALSE) -> 3
A77: =COUNTA(A2:A76) -> 75

Sheet 上下四分之间
A1: 城市 | B1: P | C1: I | D1: C | E1: O | F1: F | G1: Fo-α | H1: Wp | I1: WI | J1: WC | K1: WO | L1: WF | M1: Fo维度得分 | N1: 排序 | O1: 行政组别
A2: 烟台市 | B2: 12.5 | C2: 77.5 | D2: 91.666667 | E2: 60.374359 | F2: 66.666667 | G2: 1.0163769 | M2: 58.419518 | N2: 76 | O2: =VLOOKUP(A2,[1]Sheet1!$A$1:$I$297,2,FALSE) -> 2
A3: 梧州市 | B3: 65 | C3: 65 | D3: 66.666667 | E3: 56.091241 | F3: 60 | G3: 0.92035842 | M3: 58.280945 | N3: 77 | O3: =VLOOKUP(A3,[1]Sheet1!$A$1:$I$297,2,FALSE) -> 3
A4: 昭通市 | B4: 20 | C4: 56.25 | D4: 75 | E4: 77.079568 | F4: 60 | G4: 0.96095867 | M4: 58.221946 | N4: 78 | O4: =VLOOKUP(A4,[1]Sheet1!$A$1:$I$297,2,FALSE) -> 4
A5: 衡水市 | B5: 20 | C5: 58.75 | D5: 66.666667 | E5: 66.252309 | F5: 66.666667 | G5: 1.0861884 | M5: 58.213084 | N5: 79 | O5: =VLOOKUP(A5,[1]Sheet1!$A$1:$I$297,2,FALSE) -> 3
A6: 乌兰察布市 | B6: 65 | C6: 65 | D6: 58.333333 | E6: 48.033938 | F6: 43.333333 | G6: 1.0861884 | M6: 58.156679 | N6: 80 | O6: =VLOOKUP(A6,[1]Sheet1!$A$1:$I$297,2,FALSE) -> 4
A7: 眉山市 | B7: 42.5 | C7: 77.5 | D7: 83.333333 | E7: 53.97622 | F7: 50 | G7: 0.97240047 | M7: 58.093338 | N7: 81 | O7: =VLOOKUP(A7,[1]Sheet1!$A$1:$I$297,2,FALSE) -> 3
A8: 秦皇岛市 | B8: 10 | C8: 71.25 | D8: 66.666667 | E8: 71.789237 | F8: 43.333333 | G8: 1.0690128 | M8: 58.08547 | N8: 82 | O8: =VLOOKUP(A8,[1]Sheet1!$A$1:$I$297,2,FALSE) -> 2
A9: 西安 | B9: 77.5 | C9: 53.75 | D9: 58.333333 | E9: 54.221434 | F9: 43.333333 | G9: 0.99647244 | M9: 57.974055 | N9: 83 | O9: =VLOOKUP(A9,[1]Sheet1!$A$1:$I$297,2,FALSE) -> #N/A
A10: 张家界市 | B10: 65 | C10: 53.75 | D10: 58.333333 | E10: 64.434198 | F10: 43.333333 | G10: 0.95445588 | M10: 57.924433 | N10: 84 | O10: =VLOOKUP(A10,[1]Sheet1!$A$1:$I$297,2,FALSE) -> 4
A11: 梅州市 | B11: 20 | C11: 72.5 | D11: 83.333333 | E11: 75.333 | F11: 33.333333 | G11: 0.92035842 | M11: 57.581445 | N11: 85 | O11: =VLOOKUP(A11,[1]Sheet1!$A$1:$I$297,2,FALSE) -> 3
A12: 太原 | B12: 0 | C12: 82.5 | D12: 75 | E12: 64.768364 | F12: 60 | G12: 1.0594613 | M12: 57.447831 | N12: 86 | O12: =VLOOKUP(A12,[1]Sheet1!$A$1:$I$297,2,FALSE) -> #N/A
A13: 大连市 | B13: 67.5 | C13: 58.75 | D13: 58.333333 | E13: 58.155197 | F13: 26.666667 | G13: 1.0103917 | M13: 57.3941 | N13: 87 | O13: =VLOOKUP(A13,[1]Sheet1!$A$1:$I$297,2,FALSE) -> 1
... A149: 上海 | B149: 32.5 | C149: 60 | D149: 66.666667 | E149: 36.959129 | F149: 60 | G149: 0.98622317 | M149: 45.657097 | N149: 223 | O149: =VLOOKUP(A149,[1]Sheet1!$A$1:$I$297,2,FALSE) -> #N/A
A150: =COUNTA(A2:A149) -> 148

Sheet Last 25%
A1: 城市 | B1: P | C1: I | D1: C | E1: O | F1: F | G1: Fo-α | H1: Wp | I1: WI | J1: WC | K1: WO | L1: WF | M1: Fo维度得分 | N1: 排序 | O1: 行政组别
A2: 泸州市 | B2: 20 | C2: 43.75 | D2: 58.333333 | E2: 53.267246 | F2: 60 | G2: 0.98935981 | M2: 45.620962 | N2: 224 | O2: =VLOOKUP(A2,[1]Sheet1!$A$1:$I$297,2,FALSE) -> 3
A3: 泉州市 | B3: 20 | C3: 55 | D3: 33.333333 | E3: 63.151395 | F3: 43.333333 | G3: 0.92035842 | M3: 45.596868 | N3: 225 | O3: =VLOOKUP(A3,[1]Sheet1!$A$1:$I$297,2,FALSE) -> 2
A4: 沧州市 | B4: 10 | C4: 37.5 | D4: 41.666667 | E4: 66.219901 | F4: 33.333333 | G4: 1.0714579 | M4: 45.523651 | N4: 226 | O4: =VLOOKUP(A4,[1]Sheet1!$A$1:$I$297,2,FALSE) -> 3
A5: 商洛市 | B5: 22.5 | C5: 32.5 | D5: 41.666667 | E5: 59.347832 | F5: 60 | G5: 1.006479 | M5: 45.088761 | N5: 227 | O5: =VLOOKUP(A5,[1]Sheet1!$A$1:$I$297,2,FALSE) -> 4
A6: 信阳市 | B6: 0 | C6: 48.75 | D6: 50 | E6: 68.144977 | F6: 26.666667 | G6: 1.0109756 | M6: 44.97383 | N6: 228 | O6: =VLOOKUP(A6,[1]Sheet1!$A$1:$I$297,2,FALSE) -> 3
A7: 北海市 | B7: 10 | C7: 65 | D7: 66.666667 | E7: 47.443384 | F7: 60 | G7: 0.92035842 | M7: 44.973351 | N7: 229 | O7: =VLOOKUP(A7,[1]Sheet1!$A$1:$I$297,2,FALSE) -> 3
A8: 盐城市 | B8: 65 | C8: 60 | D8: 33.333333 | E8: 32.91982 | F8: 26.666667 | G8: 1.0215435 | M8: 44.731676 | N8: 230 | O8: =VLOOKUP(A8,[1]Sheet1!$A$1:$I$297,2,FALSE) -> 2
A9: 淮北市 | B9: 0 | C9: 60 | D9: 66.666667 | E9: 46.606425 | F9: 66.666667 | G9: 1.0380707 | M9: 44.68564 | N9: 231 | O9: =VLOOKUP(A9,[1]Sheet1!$A$1:$I$297,2,FALSE) -> 3
A10: 石嘴山市 | B10: 10 | C10: 63.75 | D10: 83.333333 | E10: 33.946905 | F10: 66.666667 | G10: 1.0861884 | M10: 44.671471 | N10: 232 | O10: =VLOOKUP(A10,[1]Sheet1!$A$1:$I$297,2,FALSE) -> 4
A11: 金华市 | B11: 10 | C11: 50 | D11: 66.666667 | E11: 54.128473 | F11: 60 | G11: 0.9213593 | M11: 44.458094 | N11: 233 | O11: =VLOOKUP(A11,[1]Sheet1!$A$1:$I$297,2,FALSE) -> 3
A12: 无锡市 | B12: 10 | C12: 53.75 | D12: 41.666667 | E12: 58.658204 | F12: 43.333333 | G12: 0.98832017 | M12: 44.415875 | N12: 234 | O12: =VLOOKUP(A12,[1]Sheet1!$A$1:$I$297,2,FALSE) -> 2
A13: 许昌市 | B13: 0 | C13: 66.25 | D13: 66.666667 | E13: 44.874516 | F13: 50 | G13: 1.0861884 | M13: 44.413539 | N13: 235 | O13: =VLOOKUP(A13,[1]Sheet1!$A$1:$I$297,2,FALSE) -> 3
... A74: 资阳市 | B74: 0 | C74: 0 | D74: 0 | E74: 54.015198 | F74: 0 | G74: 1.0151991 | M74: 21.934473 | N74: 296 | O74: =VLOOKUP(A74,[1]Sheet1!$A$1:$I$297,2,FALSE) -> 4
A75: =COUNTA(A2:A74) -> 73

Sheet P
A1: 城市 | B1: 保护森林植被碳储量的目标体系 | C1: 提高森林植被碳储量的目标体系 | D1: P环节得分
A2: 重庆 | B2: 50 | C2: 40 | D2: =AVERAGE(B2:C2) -> 45
A3: 成都 | B3: 25 | C3: 40 | D3: =AVERAGE(B3:C3) -> 32.5
A4: 上海 | B4: 25 | C4: 40 | D4: =AVERAGE(B4:C4) -> 32.5
A5: 北京 | B5: 25 | C5: 60 | D5: =AVERAGE(B5:C5) -> 42.5
A6: 周口市 | B6: 0 | C6: 40 | D6: =AVERAGE(B6:C6) -> 20
A7: 南阳市 | B7: 0 | C7: 40 | D7: =AVERAGE(B7:C7) -> 20
A8: 保定市 | B8: 0 | C8: 20 | D8: =AVERAGE(B8:C8) -> 10
A9: 临沂市 | B9: 0 | C9: 0 | D9: =AVERAGE(B9:C9) -> 0
A10: 天津 | B10: 0 | C10: 20 | D10: =AVERAGE(B10:C10) -> 10
A11: 阜阳市 | B11: 50 | C11: 80 | D11: =AVERAGE(B11:C11) -> 65
A12: 邯郸市 | B12: 0 | C12: 20 | D12: =AVERAGE(B12:C12) -> 10
A13: 石家庄 | B13: 0 | C13: 80 | D13: =AVERAGE(B13:C13) -> 40
... A298: 哈密市 | B298: 0 | C298: 0 | D298: =AVERAGE(B298:C298) -> 0
A299: =COUNTA(A2:A298) -> 297 | B299: =COUNT(B2:B298) -> 297 | C299: =COUNT(C2:C298) -> 297
B300: =B299/297 -> 1 | C300: =C299/297 -> 1

Sheet I
A1: 城市 | B1: 相关机制的完善和畅通程度 | C1: 专项资金投入力度 | D1: 人力资源保障程度 | E1: 技术条件保障程度 | F1: I环节得分
A2: 重庆 | B2: 100 | C2: 75 | D2: 60 | E2: 50 | F2: =AVERAGE(B2:E2) -> 71.25
A3: 成都 | B3: 80 | C3: 75 | D3: 80 | E3: 75 | F3: =AVERAGE(B3:E3) -> 77.5
A4: 上海 | B4: 100 | C4: 50 | D4: 40 | E4: 50 | F4: =AVERAGE(B4:E4) -> 60
A5: 北京 | B5: 100 | C5: 100 | D5: 100 | E5: 100 | F5: =AVERAGE(B5:E5) -> 100
A6: 周口市 | B6: 80 | C6: 50 | D6: 80 | E6: 50 | F6: =AVERAGE(B6:E6) -> 65
A7: 南阳市 | B7: 80 | C7: 50 | D7: 80 | E7: 50 | F7: =AVERAGE(B7:E7) -> 65
A8: 保定市 | B8: 60 | C8: 25 | D8: 80 | E8: 50 | F8: =AVERAGE(B8:E8) -> 53.75
A9: 临沂市 | B9: 60 | C9: 75 | D9: 100 | E9: 50 | F9: =AVERAGE(B9:E9) -> 71.25
A10: 天津 | B10: 60 | C10: 100 | D10: 80 | E10: 50 | F10: =AVERAGE(B10:E10) -> 72.5
A11: 阜阳市 | B11: 80 | C11: 75 | D11: 100 | E11: 50 | F11: =AVERAGE(B11:E11) -> 76.25
A12: 邯郸市 | B12: 60 | C12: 75 | D12: 100 | E12: 75 | F12: =AVERAGE(B12:E12) -> 77.5
A13: 石家庄 | B13: 60 | C13: 25 | D13: 80 | E13: 50 | F13: =AVERAGE(B13:E13) -> 53.75
... A61: 烟台市 | B61: 60 | C61: 100 | D61: 100 | E61: 50 | F61: =AVERAGE(B61:E61) -> 77.5
A62: 达州市 | B62: =VLOOKUP(A62,[2]纯数值!$A$1:$H$7,2,0) -> 80 | C62: =VLOOKUP(A62,[2]纯数值!$A$1:$H$7,3,0) -> 25 | D62: =VLOOKUP(A62,[2]纯数值!$A$1:$H$7,4,0) -> 80 | E62: =VLOOKUP(A62,[2]纯数值!$A$1:$H$7,5,0) -> 50 | F62: =AVERAGE(B62:E62) -> 58.75
A63: 聊城市 | B63: 60 | C63: 50 | D63: 80 | E63: 50 | F63: =AVERAGE(B63:E63) -> 60
A64: 永州市 | B64: 40 | C64: 0 | D64: 80 | E64: 50 | F64: =AVERAGE(B64:E64) -> 42.5
A65: 昭通市 | B65: 60 | C65: 75 | D65: 40 | E65: 50 | F65: =AVERAGE(B65:E65) -> 56.25
A66: 安阳市 | B66: 40 | C66: 25 | D66: 80 | E66: 75 | F66: =AVERAGE(B66:E66) -> 55
A67: 深圳市 | B67: 80 | C67: 75 | D67: 80 | E67: 75 | F67: =AVERAGE(B67:E67) -> 77.5
A68: 荆州市 | B68: 60 | C68: 100 | D68: 100 | E68: 50 | F68: =AVERAGE(B68:E68) -> 77.5
A69: 宁波市 | B69: 60 | C69: 75 | D69: 100 | E69: 75 | F69: =AVERAGE(B69:E69) -> 77.5
A70: 台州市 | B70: 60 | C70: 100 | D70: 100 | E70: 50 | F70: =AVERAGE(B70:E70) -> 77.5
A71: 大连市 | B71: 60 | C71: 0 | D71: 100 | E71: 75 | F71: =AVERAGE(B71:E71) -> 58.75
A72: 宜春市 | B72: 80 | C72: 100 | D72: 100 | E72: 50 | F72: =AVERAGE(B72:E72) -> 82.5
A73: 德州市 | B73: 80 | C73: 100 | D73: 80 | E73: 50 | F73: =AVERAGE(B73:E73) -> 77.5
A74: 常德市 | B74: 80 | C74: 100 | D74: 80 | E74: 50 | F74: =AVERAGE(B74:E74) -> 77.5
... A95: 安庆市 | B95: 80 | C95: 100 | D95: 100 | E95: 75 | F95: =AVERAGE(B95:E95) -> 88.75
A96: 漳州市 | B96: =VLOOKUP(A96,[2]纯数值!$A$1:$H$7,2,0) -> 0 | C96: =VLOOKUP(A96,[2]纯数值!$A$1:$H$7,3,0) -> 0 | D96: =VLOOKUP(A96,[2]纯数值!$A$1:$H$7,4,0) -> 0 | E96: =VLOOKUP(A96,[2]纯数值!$A$1:$H$7,5,0) -> 0 | F96: =AVERAGE(B96:E96) -> 0
A97: 九江市 | B97: 80 | C97: 75 | D97: 100 | E97: 100 | F97: =AVERAGE(B97:E97) -> 88.75
A98: 怀化市 | B98: 60 | C98: 100 | D98: 100 | E98: 50 | F98: =AVERAGE(B98:E98) -> 77.5
A99: 齐齐哈尔市 | B99: 40 | C99: 0 | D99: 80 | E99: 25 | F99: =AVERAGE(B99:E99) -> 36.25
A100: 无锡市 | B100: 60 | C100: 25 | D100: 80 | E100: 50 | F100: =AVERAGE(B100:E100) -> 53.75
A101: 运城市 | B101: 60 | C101: 0 | D101: 80 | E101: 50 | F101: =AVERAGE(B101:E101) -> 47.5
A102: 绥化市 | B102: 0 | C102: 0 | D102: 0 | E102: 25 | F102: =AVERAGE(B102:E102) -> 6.25
A103: 许昌市 | B103: 60 | C103: 75 | D103: 80 | E103: 50 | F103: =AVERAGE(B103:E103) -> 66.25
A104: 泸州市 | B104: 60 | C104: 25 | D104: 40 | E104: 50 | F104: =AVERAGE(B104:E104) -> 43.75
A105: 孝感市 | B105: 80 | C105: 50 | D105: 20 | E105: 50 | F105: =AVERAGE(B105:E105) -> 50
A106: 金华市 | B106: 60 | C106: 50 | D106: 40 | E106: 50 | F106: =AVERAGE(B106:E106) -> 50
A107: 廊坊市 | B107: 60 | C107: 25 | D107: 80 | E107: 50 | F107: =AVERAGE(B107:E107) -> 53.75
...

Sheet C
A1: 城市 | B1: 落实监督行为的机制保障 | C1: 落实监督行为的资源保障 | D1: 监督行为的体现形式 | E1: C环节得分
A2: 重庆 | B2: 50 | C2: 50 | D2: 50 | E2: =AVERAGE(B2:D2) -> 50
A3: 成都 | B3: 100 | C3: 75 | D3: 50 | E3: =AVERAGE(B3:D3) -> 75
A4: 上海 | B4: 50 | C4: 75 | D4: 75 | E4: =AVERAGE(B4:D4) -> 66.666667
A5: 北京 | B5: 100 | C5: 100 | D5: 75 | E5: =AVERAGE(B5:D5) -> 91.666667
A6: 周口市 | B6: 75 | C6: 100 | D6: 75 | E6: =AVERAGE(B6:D6) -> 83.333333
A7: 南阳市 | B7: 75 | C7: 0 | D7: 50 | E7: =AVERAGE(B7:D7) -> 41.666667
A8: 保定市 | B8: 75 | C8: 0 | D8: 50 | E8: =AVERAGE(B8:D8) -> 41.666667
A9: 临沂市 | B9: 75 | C9: 75 | D9: 75 | E9: =AVERAGE(B9:D9) -> 75
A10: 天津 | B10: 100 | C10: 50 | D10: 50 | E10: =AVERAGE(B10:D10) -> 66.666667
A11: 阜阳市 | B11: 75 | C11: 100 | D11: 50 | E11: =AVERAGE(B11:D11) -> 75
A12: 邯郸市 | B12: 100 | C12: 50 | D12: 50 | E12: =AVERAGE(B12:D12) -> 66.666667
A13: 石家庄 | B13: 100 | C13: 25 | D13: 75 | E13: =AVERAGE(B13:D13) -> 66.666667
... A61: 烟台市 | B61: 100 | C61: 100 | D61: 75 | E61: =AVERAGE(B61:D61) -> 91.666667
A62: 达州市 | B62: =VLOOKUP(A62,[2]纯数值!$A$1:$H$7,6,0) -> 25 | C62: =VLOOKUP(A62,[2]纯数值!$A$1:$H$7,7,0) -> 0 | D62: =VLOOKUP(A62,[2]纯数值!$A$1:$H$7,8,0) -> 75 | E62: =AVERAGE(B62:D62) -> 33.333333
A63: 聊城市 | B63: 50 | C63: 50 | D63: 75 | E63: =AVERAGE(B63:D63) -> 58.333333
A64: 永州市 | B64: 75 | C64: 25 | D64: 50 | E64: =AVERAGE(B64:D64) -> 50
A65: 昭通市 | B65: 100 | C65: 75 | D65: 50 | E65: =AVERAGE(B65:D65) -> 75
A66: 安阳市 | B66: 100 | C66: 100 | D66: 50 | E66: =AVERAGE(B66:D66) -> 83.333333
A67: 深圳市 | B67: 100 | C67: 50 | D67: 75 | E67: =AVERAGE(B67:D67) -> 75
A68: 荆州市 | B68: 100 | C68: 100 | D68: 75 | E68: =AVERAGE(B68:D68) -> 91.666667
A69: 宁波市 | B69: 100 | C69: 75 | D69: 50 | E69: =AVERAGE(B69:D69) -> 75
A70: 台州市 | B70: 100 | C70: 75 | D70: 75 | E70: =AVERAGE(B70:D70) -> 83.333333
A71: 大连市 | B71: 100 | C71: 25 | D71: 50 | E71: =AVERAGE(B71:D71) -> 58.333333
A72: 宜春市 | B72: 100 | C72: 100 | D72: 50 | E72: =AVERAGE(B72:D72) -> 83.333333
A73: 德州市 | B73: 75 | C73: 100 | D73: 75 | E73: =AVERAGE(B73:D73) -> 83.333333
A74: 常德市 | B74: 100 | C74: 75 | D74: 75 | E74: =AVERAGE(B74:D74) -> 83.333333
... A95: 安庆市 | B95: 75 | C95: 75 | D95: 50 | E95: =AVERAGE(B95:D95) -> 66.666667
A96: 漳州市 | B96: =VLOOKUP(A96,[2]纯数值!$A$1:$H$7,6,0) -> 0 | C96: =VLOOKUP(A96,[2]纯数值!$A$1:$H$7,7,0) -> 0 | D96: =VLOOKUP(A96,[2]纯数值!$A$1:$H$7,8,0) -> 25 | E96: =AVERAGE(B96:D96) -> 8.3333333
A97: 九江市 | B97: 100 | C97: 100 | D97: 75 | E97: =AVERAGE(B97:D97) -> 91.666667
A98: 怀化市 | B98: 100 | C98: 75 | D98: 75 | E98: =AVERAGE(B98:D98) -> 83.333333
A99: 齐齐哈尔市 | B99: 50 | C99: 75 | D99: 50 | E99: =AVERAGE(B99:D99) -> 58.333333
A100: 无锡市 | B100: 50 | C100: 50 | D100: 25 | E100: =AVERAGE(B100:D100) -> 41.666667
A101: 运城市 | B101: 75 | C101: 50 | D101: 0 | E101: =AVERAGE(B101:D101) -> 41.666667
A102: 绥化市 | B102: =VLOOKUP(A102,[2]纯数值!$A$1:$H$7,6,0) -> 0 | C102: =VLOOKUP(A102,[2]纯数值!$A$1:$H$7,7,0) -> 0 | D102: =VLOOKUP(A102,[2]纯数值!$A$1:$H$7,8,0) -> 25 | E102: =AVERAGE(B102:D102) -> 8.3333333
A103: 许昌市 | B103: 100 | C103: 50 | D103: 50 | E103: =AVERAGE(B103:D103) -> 66.666667
A104: 泸州市 | B104: 75 | C104: 75 | D104: 25 | E104: =AVERAGE(B104:D104) -> 58.333333
A105: 孝感市 | B105: 50 | C105: 100 | D105: 50 | E105: =AVERAGE(B105:D105) -> 66.666667
A106: 金华市 | B106: 100 | C106: 75 | D106: 25 | E106: =AVERAGE(B106:D106) -> 66.666667
A107: 廊坊市 | B107: 75 | C107: 25 | D107: 25 | E107: =AVERAGE(B107:D107) -> 41.666667
...

Sheet O
B1: 城市 | C1: 森林覆盖率（%） | D1: 森林植被碳储量（万吨） | E1: 森林火灾受害率（‰） | F1: 林业有害生物成灾率（‰） | G1: O环节得分 | H1: 碳储量公式：TC=V*δ*ρ*γ. Δ=1.9; ρ=0.5t/m3; γ=0.5
B2: 重庆市 | C2: 100 | D2: 57.05906 | E2: 97.943144 | F2: 81.763706 | G2: =AVERAGE(C2:F2) -> 84.191477
B3: 成都市 | C3: 100 | D3: 8.7048763 | E3: 94.85786 | F3: 83.471637 | G3: =AVERAGE(C3:F3) -> 71.758593
B4: 上海市 | C4: 40 | D4: 0.94614054 | E4: 53.720736 | F4: 53.169638 | G4: =AVERAGE(C4:F4) -> 36.959129
B5: 北京市 | C5: 100 | D5: 5.681408 | E5: 53.720736 | F5: 53.169638 | G5: =AVERAGE(C5:F5) -> 53.142945
B6: 周口市 | C6: 20 | D6: 1.8458414 | E6: 53.720736 | F6: 79.064073 | G6: =AVERAGE(C6:F6) -> 38.657663
B7: 南阳市 | C7: 100 | D7: 9.6661356 | E7: 53.720736 | F7: 79.064073 | G7: =AVERAGE(C7:F7) -> 60.612736
B8: 保定市 | C8: 80 | D8: 8.8358207 | E8: 84.573579 | F8: 99.283771 | G8: =AVERAGE(C8:F8) -> 68.173293
B9: 临沂市 | C9: 60 | D9: 3.787301 | E9: 74.289298 | F9: 72.452728 | G9: =AVERAGE(C9:F9) -> 52.632332
B10: 天津市 | C10: 40 | D10: 1.1829039 | E10: 53.720736 | F10: 53.169638 | G10: =AVERAGE(C10:F10) -> 37.018319
B11: 阜阳市 | C11: 60 | D11: 3.1006872 | E11: 74.289298 | F11: 94.435451 | G11: =AVERAGE(C11:F11) -> 57.956359
B12: 邯郸市 | C12: 100 | D12: 2.4474908 | E12: 84.573579 | F12: 99.283771 | G12: =AVERAGE(C12:F12) -> 71.57621
B13: 石家庄市 | C13: 100 | D13: 2.9331061 | E13: 84.573579 | F13: 99.283771 | G13: =AVERAGE(C13:F13) -> 71.697614
B14: 徐州市 | C14: 60 | D14: 3.3195072 | E14: 84.573579 | F14: 88.981091 | G14: =AVERAGE(C14:F14) -> 59.218544
A15: =VLOOKUP(B15,#REF!,2,FALSE) -> #REF! | B15: 菏泽市 | C15: 60 | D15: 1.8053411 | E15: 53.720736 | F15: 53.169638 | G15: =AVERAGE(C15:F15) -> 42.173929
B16: 商丘市 | C16: 40 | D16: 2.2069529 | E16: 53.720736 | F16: 79.064073 | G16: =AVERAGE(C16:F16) -> 43.747941
B17: 广州市 | C17: 100 | D17: 4.6275742 | E17: 98.971572 | F17: 96.9698 | G17: =AVERAGE(C17:F17) -> 75.142237
B18: 西安市 | C18: 100 | D18: 9.9953625 | E18: 53.720736 | F18: 53.169638 | G18: =AVERAGE(C18:F18) -> 54.221434
B19: 赣州市 | C19: 100 | D19: 27.656009 | E19: 91.258361 | F19: 0 | G19: =AVERAGE(C19:F19) -> 54.728592
B20: 驻马店市 | C20: 80 | D20: 4.0027557 | E20: 100 | F20: 99.118487 | G20: =AVERAGE(C20:F20) -> 70.780311
B21: 毕节市 | C21: 100 | D21: 14.702093 | E21: 99.907441 | F21: 98.347164 | G21: =AVERAGE(C21:F21) -> 78.239174
B22: 哈尔滨市 | C22: 100 | D22: 25.332768 | E22: 53.720736 | F22: 85.124473 | G22: =AVERAGE(C22:F22) -> 66.044494
B23: 武汉市 | C23: 40 | D23: 1.9319522 | E23: 100 | F23: 98.071691 | G23: =AVERAGE(C23:F23) -> 60.000911
B24: 潍坊市 | C24: 60 | D24: 1.6445925 | E24: 53.720736 | F24: 53.169638 | G24: =AVERAGE(C24:F24) -> 42.133742
B25: 郑州市 | C25: 60 | D25: 1.1284483 | E25: 53.720736 | F25: 79.064073 | G25: =AVERAGE(C25:F25) -> 48.478314
B26: 信阳市 | C26: 100 | D26: 8.9422552 | E26: 84.573579 | F26: 79.064073 | G26: =AVERAGE(C26:F26) -> 68.144977
A27: =VLOOKUP(B27,#REF!,2,FALSE) -> #REF! | B27: 济宁市 | C27: 80 | D27: 1.432142 | E27: 53.720736 | F27: 53.169638 | G27: =AVERAGE(C27:F27) -> 47.080629
A28: =VLOOKUP(B28,#REF!,2,FALSE) -> #REF! | B28: 湛江市 | C28: 60 | D28: 7.3918409 | E28: 96.914716 | F28: 87.328255 | G28: =AVERAGE(C28:F28) -> 62.908703
B29: 长春市 | C29: 20 | D29: 6.2424899 | E29: 94.85786 | F29: 84.022582 | G29: =AVERAGE(C29:F29) -> 51.280733
B30: 青岛市 | C30: 40 | D30: 2.5608667 | E30: 74.289298 | F30: 53.169638 | G30: =AVERAGE(C30:F30) -> 42.504951
B31: 杭州市 | C31: 100 | D31: 16.07532 | E31: 99.64005 | F31: 53.169638 | G31: =AVERAGE(C31:F31) -> 67.221252
B32: 温州市 | C32: 100 | D32: 9.3749166 | E32: 53.720736 | F32: 53.169638 | G32: =AVERAGE(C32:F32) -> 54.066323
B33: 茂名市 | C33: 100 | D33: 7.1019883 | E33: 96.914716 | F33: 87.328255 | G33: =AVERAGE(C33:F33) -> 72.83624
B34: 遵义市 | C34: 100 | D34: 29.243767 | E34: 99.696614 | F34: 99.079921 | G34: =AVERAGE(C34:F34) -> 82.005076
B35: 济南市 | C35: 60 | D35: 2.4887581 | E35: 53.720736 | F35: 53.169638 | G35: =AVERAGE(C35:F35) -> 42.344783
B36: 邵阳市 | C36: 100 | D36: 19.88721 | E36: 53.720736 | F36: 83.471637 | G36: =AVERAGE(C36:F36) -> 64.269896
B37: 盐城市 | C37: 40 | D37: 2.6981895 | E37: 0 | F37: 88.981091 | G37: =AVERAGE(C37:F37) -> 32.91982
B38: 南宁市 | C38: 100 | D38: 15.130634 | E38: 95.886288 | F38: 98.732825 | G38: =AVERAGE(C38:F38) -> 77.437437
B39: 邢台市 | C39: 80 | D39: 2.1536337 | E39: 84.573579 | F39: 88.981091 | G39: =AVERAGE(C39:F39) -> 63.927076
B40: 合肥市 | C40: 60 | D40: 2.3809266 | E40: 74.289298 | F40: 70.248946 | G40: =AVERAGE(C40:F40) -> 51.729793
...

Sheet F
A1: 城市 | B1: 森林碳汇建设工作的总结 | C1: 奖励对提升森林碳汇水平有突出贡献的主体 | D1: 处罚破坏森林碳汇的主体 | E1: F环节得分
A2: 重庆 | B2: 80 | C2: 50 | D2: 0 | E2: =AVERAGE(B2:D2) -> 43.333333
A3: 成都 | B3: 80 | C3: 50 | D3: 50 | E3: =AVERAGE(B3:D3) -> 60
A4: 上海 | B4: 80 | C4: 50 | D4: 50 | E4: =AVERAGE(B4:D4) -> 60
A5: 北京 | B5: 100 | C5: 50 | D5: 50 | E5: =AVERAGE(B5:D5) -> 66.666667
A6: 周口市 | B6: 80 | C6: 50 | D6: 0 | E6: =AVERAGE(B6:D6) -> 43.333333
A7: 南阳市 | B7: 80 | C7: 50 | D7: 50 | E7: =AVERAGE(B7:D7) -> 60
A8: 保定市 | B8: 80 | C8: 0 | D8: 0 | E8: =AVERAGE(B8:D8) -> 26.666667
A9: 临沂市 | B9: 80 | C9: 50 | D9: 50 | E9: =AVERAGE(B9:D9) -> 60
A10: 天津 | B10: 100 | C10: 50 | D10: 50 | E10: =AVERAGE(B10:D10) -> 66.666667
A11: 阜阳市 | B11: 80 | C11: 0 | D11: 50 | E11: =AVERAGE(B11:D11) -> 43.333333
A12: 邯郸市 | B12: 100 | C12: 50 | D12: 50 | E12: =AVERAGE(B12:D12) -> 66.666667
A13: 石家庄 | B13: 80 | C13: 50 | D13: 0 | E13: =AVERAGE(B13:D13) -> 43.333333
... A52: 南京 | B52: 80 | C52: 0 | D52: 0 | E52: =AVERAGE(B52:D52) -> 26.666667
A53: 黄冈市 | B53: =VLOOKUP(A53,[3]纯数值!$A$1:$D$11,2,0) -> 80 | C53: =VLOOKUP(A53,[3]纯数值!$A$1:$D$11,3,0) -> 50 | D53: =VLOOKUP(A53,[3]纯数值!$A$1:$D$11,4,0) -> 50 | E53: =AVERAGE(B53:D53) -> 60
A54: 福州 | B54: 80 | C54: 0 | D54: 0 | E54: =AVERAGE(B54:D54) -> 26.666667
A55: 南充市 | B55: 80 | C55: 0 | D55: 50 | E55: =AVERAGE(B55:D55) -> 43.333333
A56: 揭阳市 | B56: 100 | C56: 50 | D56: 50 | E56: =AVERAGE(B56:D56) -> 66.666667
A57: 曲靖市 | B57: 80 | C57: 0 | D57: 0 | E57: =AVERAGE(B57:D57) -> 26.666667
A58: 亳州市 | B58: 80 | C58: 50 | D58: 50 | E58: =AVERAGE(B58:D58) -> 60
A59: 新乡市 | B59: 80 | C59: 50 | D59: 50 | E59: =AVERAGE(B59:D59) -> 60
A60: 宿州市 | B60: 80 | C60: 50 | D60: 50 | E60: =AVERAGE(B60:D60) -> 60
A61: 烟台市 | B61: 100 | C61: 50 | D61: 50 | E61: =AVERAGE(B61:D61) -> 66.666667
A62: 达州市 | B62: =VLOOKUP(A62,[3]纯数值!$A$1:$D$11,2,0) -> 80 | C62: =VLOOKUP(A62,[3]纯数值!$A$1:$D$11,3,0) -> 0 | D62: =VLOOKUP(A62,[3]纯数值!$A$1:$D$11,4,0) -> 0 | E62: =AVERAGE(B62:D62) -> 26.666667
A63: 聊城市 | B63: 80 | C63: 50 | D63: 0 | E63: =AVERAGE(B63:D63) -> 43.333333
A64: 永州市 | B64: 80 | C64: 0 | D64: 0 | E64: =AVERAGE(B64:D64) -> 26.666667
A65: 昭通市 | B65: 80 | C65: 50 | D65: 50 | E65: =AVERAGE(B65:D65) -> 60
A66: 安阳市 | B66: 80 | C66: 50 | D66: 0 | E66: =AVERAGE(B66:D66) -> 43.333333
A67: 深圳市 | B67: 100 | C67: 0 | D67: 0 | E67: =AVERAGE(B67:D67) -> 33.333333
A68: 荆州市 | B68: 100 | C68: 0 | D68: 50 | E68: =AVERAGE(B68:D68) -> 50
A69: 宁波市 | B69: 100 | C69: 50 | D69: 0 | E69: =AVERAGE(B69:D69) -> 50
A70: 台州市 | B70: 80 | C70: 0 | D70: 50 | E70: =AVERAGE(B70:D70) -> 43.333333
A71: 大连市 | B71: 80 | C71: 0 | D71: 0 | E71: =AVERAGE(B71:D71) -> 26.666667
A72: 宜春市 | B72: 80 | C72: 50 | D72: 50 | E72: =AVERAGE(B72:D72) -> 60
A73: 德州市 | B73: 80 | C73: 0 | D73: 50 | E73: =AVERAGE(B73:D73) -> 43.333333
A74: 常德市 | B74: 100 | C74: 50 | D74: 50 | E74: =AVERAGE(B74:D74) -> 66.666667
... A98: 怀化市 | B98: 100 | C98: 50 | D98: 50 | E98: =AVERAGE(B98:D98) -> 66.666667
A99: 齐齐哈尔市 | B99: =VLOOKUP(A99,[3]纯数值!$A$1:$D$11,2,0) -> 80 | C99: =VLOOKUP(A99,[3]纯数值!$A$1:$D$11,3,0) -> 0 | D99: =VLOOKUP(A99,[3]纯数值!$A$1:$D$11,4,0) -> 0 | E99: =AVERAGE(B99:D99) -> 26.666667
A100: 无锡市 | B100: 80 | C100: 50 | D100: 0 | E100: =AVERAGE(B100:D100) -> 43.333333
A101: 运城市 | B101: 40 | C101: 0 | D101: 0 | E101: =AVERAGE(B101:D101) -> 13.333333
...
